2016-09-05 09:08:44,992 [Thread-3:140016482998016] [django.request:256] [base:handle_uncaught_exception] [ERROR]- Internal Server Error: /AddBasicInfo/
Traceback (most recent call last):
  File "/usr/local/lib/python2.7/dist-packages/django/core/handlers/base.py", line 132, in get_response
    response = wrapped_callback(request, *callback_args, **callback_kwargs)
  File "/home/zzj/PycharmProjects/VOAM/website/views.py", line 37, in AddBasicInfo
    return render_to_response('AddBasicInfo.html', {'devicestatusform': devicestatusform,'devicegroupform':devicegroupform,'deviceregionform':deviceregionform,'videodirectionform':videodirectionform,'videotypeform':videotypeform,'devicebrandform':devicebrandform,'devicetypeform':devicetypeform,'devicebrandid':devicebrandid})
  File "/usr/local/lib/python2.7/dist-packages/django/shortcuts.py", line 39, in render_to_response
    content = loader.render_to_string(template_name, context, using=using)
  File "/usr/local/lib/python2.7/dist-packages/django/template/loader.py", line 99, in render_to_string
    return template.render(context, request)
  File "/usr/local/lib/python2.7/dist-packages/django/template/backends/django.py", line 74, in render
    return self.template.render(context)
  File "/usr/local/lib/python2.7/dist-packages/django/template/base.py", line 210, in render
    return self._render(context)
  File "/usr/local/lib/python2.7/dist-packages/django/template/base.py", line 202, in _render
    return self.nodelist.render(context)
  File "/usr/local/lib/python2.7/dist-packages/django/template/base.py", line 905, in render
    bit = self.render_node(node, context)
  File "/usr/local/lib/python2.7/dist-packages/django/template/debug.py", line 79, in render_node
    return node.render(context)
  File "/usr/local/lib/python2.7/dist-packages/django/template/defaulttags.py", line 162, in render
    len_values = len(values)
  File "/usr/local/lib/python2.7/dist-packages/django/db/models/query.py", line 144, in __len__
    self._fetch_all()
  File "/usr/local/lib/python2.7/dist-packages/django/db/models/query.py", line 965, in _fetch_all
    self._result_cache = list(self.iterator())
  File "/usr/local/lib/python2.7/dist-packages/django/db/models/query.py", line 238, in iterator
    results = compiler.execute_sql()
  File "/usr/local/lib/python2.7/dist-packages/django/db/models/sql/compiler.py", line 840, in execute_sql
    cursor.execute(sql, params)
  File "/usr/local/lib/python2.7/dist-packages/django/db/backends/utils.py", line 79, in execute
    return super(CursorDebugWrapper, self).execute(sql, params)
  File "/usr/local/lib/python2.7/dist-packages/django/db/backends/utils.py", line 64, in execute
    return self.cursor.execute(sql, params)
  File "/usr/local/lib/python2.7/dist-packages/django/db/utils.py", line 98, in __exit__
    six.reraise(dj_exc_type, dj_exc_value, traceback)
  File "/usr/local/lib/python2.7/dist-packages/django/db/backends/utils.py", line 64, in execute
    return self.cursor.execute(sql, params)
  File "/usr/local/lib/python2.7/dist-packages/django/db/backends/mysql/base.py", line 124, in execute
    return self.cursor.execute(query, args)
  File "/usr/lib/python2.7/dist-packages/MySQLdb/cursors.py", line 226, in execute
    self.errorhandler(self, exc, value)
  File "/usr/lib/python2.7/dist-packages/MySQLdb/connections.py", line 36, in defaulterrorhandler
    raise errorvalue
ProgrammingError: (1146, "Table 'voam.website_devicebrand' doesn't exist")
2016-09-05 09:08:46,065 [Thread-4:140016482998016] [django.request:170] [base:get_response] [WARNING]- Not Found: /favicon.ico
2016-09-05 09:24:35,314 [Thread-7:140334258775808] [django.request:256] [base:handle_uncaught_exception] [ERROR]- Internal Server Error: /AddBasicInfo/
Traceback (most recent call last):
  File "/usr/local/lib/python2.7/dist-packages/django/core/handlers/base.py", line 132, in get_response
    response = wrapped_callback(request, *callback_args, **callback_kwargs)
  File "/home/zzj/PycharmProjects/VOAM/website/views.py", line 26, in AddBasicInfo
    result = DeviceStatus.objects.filter(devicestatus=devicestatus).count()
  File "/usr/local/lib/python2.7/dist-packages/django/db/models/manager.py", line 127, in manager_method
    return getattr(self.get_queryset(), name)(*args, **kwargs)
  File "/usr/local/lib/python2.7/dist-packages/django/db/models/query.py", line 679, in filter
    return self._filter_or_exclude(False, *args, **kwargs)
  File "/usr/local/lib/python2.7/dist-packages/django/db/models/query.py", line 697, in _filter_or_exclude
    clone.query.add_q(Q(*args, **kwargs))
  File "/usr/local/lib/python2.7/dist-packages/django/db/models/sql/query.py", line 1310, in add_q
    clause, require_inner = self._add_q(where_part, self.used_aliases)
  File "/usr/local/lib/python2.7/dist-packages/django/db/models/sql/query.py", line 1338, in _add_q
    allow_joins=allow_joins, split_subq=split_subq,
  File "/usr/local/lib/python2.7/dist-packages/django/db/models/sql/query.py", line 1150, in build_filter
    lookups, parts, reffed_expression = self.solve_lookup_type(arg)
  File "/usr/local/lib/python2.7/dist-packages/django/db/models/sql/query.py", line 1036, in solve_lookup_type
    _, field, _, lookup_parts = self.names_to_path(lookup_splitted, self.get_meta())
  File "/usr/local/lib/python2.7/dist-packages/django/db/models/sql/query.py", line 1397, in names_to_path
    "Choices are: %s" % (name, ", ".join(available)))
FieldError: Cannot resolve keyword 'devicestatus' into field. Choices are: id, name
2016-09-05 09:29:33,019 [Thread-3:140575047071488] [django.request:256] [base:handle_uncaught_exception] [ERROR]- Internal Server Error: /AddBasicInfo/
Traceback (most recent call last):
  File "/usr/local/lib/python2.7/dist-packages/django/core/handlers/base.py", line 132, in get_response
    response = wrapped_callback(request, *callback_args, **callback_kwargs)
  File "/home/zzj/PycharmProjects/VOAM/website/views.py", line 27, in AddBasicInfo
    result = DeviceStatus.objects.filter(devicestatus=devicestatus).count()
  File "/usr/local/lib/python2.7/dist-packages/django/db/models/manager.py", line 127, in manager_method
    return getattr(self.get_queryset(), name)(*args, **kwargs)
  File "/usr/local/lib/python2.7/dist-packages/django/db/models/query.py", line 679, in filter
    return self._filter_or_exclude(False, *args, **kwargs)
  File "/usr/local/lib/python2.7/dist-packages/django/db/models/query.py", line 697, in _filter_or_exclude
    clone.query.add_q(Q(*args, **kwargs))
  File "/usr/local/lib/python2.7/dist-packages/django/db/models/sql/query.py", line 1310, in add_q
    clause, require_inner = self._add_q(where_part, self.used_aliases)
  File "/usr/local/lib/python2.7/dist-packages/django/db/models/sql/query.py", line 1338, in _add_q
    allow_joins=allow_joins, split_subq=split_subq,
  File "/usr/local/lib/python2.7/dist-packages/django/db/models/sql/query.py", line 1150, in build_filter
    lookups, parts, reffed_expression = self.solve_lookup_type(arg)
  File "/usr/local/lib/python2.7/dist-packages/django/db/models/sql/query.py", line 1036, in solve_lookup_type
    _, field, _, lookup_parts = self.names_to_path(lookup_splitted, self.get_meta())
  File "/usr/local/lib/python2.7/dist-packages/django/db/models/sql/query.py", line 1397, in names_to_path
    "Choices are: %s" % (name, ", ".join(available)))
FieldError: Cannot resolve keyword 'devicestatus' into field. Choices are: id, name
2016-09-05 09:35:02,816 [Thread-3:140154758657792] [django.request:256] [base:handle_uncaught_exception] [ERROR]- Internal Server Error: /AddBasicInfo/
Traceback (most recent call last):
  File "/usr/local/lib/python2.7/dist-packages/django/core/handlers/base.py", line 132, in get_response
    response = wrapped_callback(request, *callback_args, **callback_kwargs)
  File "/home/zzj/PycharmProjects/VOAM/website/views.py", line 28, in AddBasicInfo
    result = DeviceStatus.objects.filter(devicestatus=devicestatus).count()
  File "/usr/local/lib/python2.7/dist-packages/django/db/models/manager.py", line 127, in manager_method
    return getattr(self.get_queryset(), name)(*args, **kwargs)
  File "/usr/local/lib/python2.7/dist-packages/django/db/models/query.py", line 679, in filter
    return self._filter_or_exclude(False, *args, **kwargs)
  File "/usr/local/lib/python2.7/dist-packages/django/db/models/query.py", line 697, in _filter_or_exclude
    clone.query.add_q(Q(*args, **kwargs))
  File "/usr/local/lib/python2.7/dist-packages/django/db/models/sql/query.py", line 1310, in add_q
    clause, require_inner = self._add_q(where_part, self.used_aliases)
  File "/usr/local/lib/python2.7/dist-packages/django/db/models/sql/query.py", line 1338, in _add_q
    allow_joins=allow_joins, split_subq=split_subq,
  File "/usr/local/lib/python2.7/dist-packages/django/db/models/sql/query.py", line 1150, in build_filter
    lookups, parts, reffed_expression = self.solve_lookup_type(arg)
  File "/usr/local/lib/python2.7/dist-packages/django/db/models/sql/query.py", line 1036, in solve_lookup_type
    _, field, _, lookup_parts = self.names_to_path(lookup_splitted, self.get_meta())
  File "/usr/local/lib/python2.7/dist-packages/django/db/models/sql/query.py", line 1397, in names_to_path
    "Choices are: %s" % (name, ", ".join(available)))
FieldError: Cannot resolve keyword 'devicestatus' into field. Choices are: id, name
2016-09-05 09:36:41,076 [Thread-5:140154758657792] [django.request:256] [base:handle_uncaught_exception] [ERROR]- Internal Server Error: /AddBasicInfo/
Traceback (most recent call last):
  File "/usr/local/lib/python2.7/dist-packages/django/core/handlers/base.py", line 132, in get_response
    response = wrapped_callback(request, *callback_args, **callback_kwargs)
  File "/home/zzj/PycharmProjects/VOAM/website/views.py", line 28, in AddBasicInfo
    result = DeviceStatus.objects.filter(devicestatus=devicestatus).count()
  File "/usr/local/lib/python2.7/dist-packages/django/db/models/manager.py", line 127, in manager_method
    return getattr(self.get_queryset(), name)(*args, **kwargs)
  File "/usr/local/lib/python2.7/dist-packages/django/db/models/query.py", line 679, in filter
    return self._filter_or_exclude(False, *args, **kwargs)
  File "/usr/local/lib/python2.7/dist-packages/django/db/models/query.py", line 697, in _filter_or_exclude
    clone.query.add_q(Q(*args, **kwargs))
  File "/usr/local/lib/python2.7/dist-packages/django/db/models/sql/query.py", line 1310, in add_q
    clause, require_inner = self._add_q(where_part, self.used_aliases)
  File "/usr/local/lib/python2.7/dist-packages/django/db/models/sql/query.py", line 1338, in _add_q
    allow_joins=allow_joins, split_subq=split_subq,
  File "/usr/local/lib/python2.7/dist-packages/django/db/models/sql/query.py", line 1150, in build_filter
    lookups, parts, reffed_expression = self.solve_lookup_type(arg)
  File "/usr/local/lib/python2.7/dist-packages/django/db/models/sql/query.py", line 1036, in solve_lookup_type
    _, field, _, lookup_parts = self.names_to_path(lookup_splitted, self.get_meta())
  File "/usr/local/lib/python2.7/dist-packages/django/db/models/sql/query.py", line 1397, in names_to_path
    "Choices are: %s" % (name, ", ".join(available)))
FieldError: Cannot resolve keyword 'devicestatus' into field. Choices are: id, name
2016-09-05 09:45:04,512 [Thread-3:139905444968192] [django.request:256] [base:handle_uncaught_exception] [ERROR]- Internal Server Error: /AddBasicInfo/
Traceback (most recent call last):
  File "/usr/local/lib/python2.7/dist-packages/django/core/handlers/base.py", line 132, in get_response
    response = wrapped_callback(request, *callback_args, **callback_kwargs)
  File "/home/zzj/PycharmProjects/VOAM/website/views.py", line 28, in AddBasicInfo
    result = DeviceStatus.objects.filter(devicestatus=devicestatus).count()
  File "/usr/local/lib/python2.7/dist-packages/django/db/models/manager.py", line 127, in manager_method
    return getattr(self.get_queryset(), name)(*args, **kwargs)
  File "/usr/local/lib/python2.7/dist-packages/django/db/models/query.py", line 679, in filter
    return self._filter_or_exclude(False, *args, **kwargs)
  File "/usr/local/lib/python2.7/dist-packages/django/db/models/query.py", line 697, in _filter_or_exclude
    clone.query.add_q(Q(*args, **kwargs))
  File "/usr/local/lib/python2.7/dist-packages/django/db/models/sql/query.py", line 1310, in add_q
    clause, require_inner = self._add_q(where_part, self.used_aliases)
  File "/usr/local/lib/python2.7/dist-packages/django/db/models/sql/query.py", line 1338, in _add_q
    allow_joins=allow_joins, split_subq=split_subq,
  File "/usr/local/lib/python2.7/dist-packages/django/db/models/sql/query.py", line 1150, in build_filter
    lookups, parts, reffed_expression = self.solve_lookup_type(arg)
  File "/usr/local/lib/python2.7/dist-packages/django/db/models/sql/query.py", line 1036, in solve_lookup_type
    _, field, _, lookup_parts = self.names_to_path(lookup_splitted, self.get_meta())
  File "/usr/local/lib/python2.7/dist-packages/django/db/models/sql/query.py", line 1397, in names_to_path
    "Choices are: %s" % (name, ", ".join(available)))
FieldError: Cannot resolve keyword 'devicestatus' into field. Choices are: id, name
2016-09-05 09:45:32,672 [Thread-3:139764313126656] [django.request:256] [base:handle_uncaught_exception] [ERROR]- Internal Server Error: /AddBasicInfo/
Traceback (most recent call last):
  File "/usr/local/lib/python2.7/dist-packages/django/core/handlers/base.py", line 132, in get_response
    response = wrapped_callback(request, *callback_args, **callback_kwargs)
  File "/home/zzj/PycharmProjects/VOAM/website/views.py", line 31, in AddBasicInfo
    DeviceStatus.objects.create(devicestatus=devicestatus)
  File "/usr/local/lib/python2.7/dist-packages/django/db/models/manager.py", line 127, in manager_method
    return getattr(self.get_queryset(), name)(*args, **kwargs)
  File "/usr/local/lib/python2.7/dist-packages/django/db/models/query.py", line 346, in create
    obj = self.model(**kwargs)
  File "/usr/local/lib/python2.7/dist-packages/django/db/models/base.py", line 480, in __init__
    raise TypeError("'%s' is an invalid keyword argument for this function" % list(kwargs)[0])
TypeError: 'devicestatus' is an invalid keyword argument for this function
2016-09-05 11:45:08,497 [Thread-2:140169989203712] [django.request:256] [base:handle_uncaught_exception] [ERROR]- Internal Server Error: /AddBasicInfo/
Traceback (most recent call last):
  File "/usr/local/lib/python2.7/dist-packages/django/core/handlers/base.py", line 132, in get_response
    response = wrapped_callback(request, *callback_args, **callback_kwargs)
  File "/home/zzj/PycharmProjects/VOAM/website/views.py", line 29, in AddBasicInfo
    print '收到的消息：%s %s %s %s %s %s %s '%(devicestatus,devicegroup,deviceregion,videodirection,videotype,devicebrand,devicetype)
UnicodeDecodeError: 'ascii' codec can't decode byte 0xe6 in position 0: ordinal not in range(128)
2016-09-05 11:49:24,282 [Thread-3:139811529537280] [django.request:256] [base:handle_uncaught_exception] [ERROR]- Internal Server Error: /AddBasicInfo/
Traceback (most recent call last):
  File "/usr/local/lib/python2.7/dist-packages/django/core/handlers/base.py", line 151, in get_response
    % (callback.__module__, view_name))
ValueError: The view website.views.AddBasicInfo didn't return an HttpResponse object. It returned None instead.
2016-09-05 11:50:03,394 [Thread-3:140191759070976] [django.request:256] [base:handle_uncaught_exception] [ERROR]- Internal Server Error: /AddBasicInfo/
Traceback (most recent call last):
  File "/usr/local/lib/python2.7/dist-packages/django/core/handlers/base.py", line 151, in get_response
    % (callback.__module__, view_name))
ValueError: The view website.views.AddBasicInfo didn't return an HttpResponse object. It returned None instead.
2016-09-05 11:50:49,025 [Thread-3:140301184968448] [django.request:256] [base:handle_uncaught_exception] [ERROR]- Internal Server Error: /AddBasicInfo/
Traceback (most recent call last):
  File "/usr/local/lib/python2.7/dist-packages/django/core/handlers/base.py", line 151, in get_response
    % (callback.__module__, view_name))
ValueError: The view website.views.AddBasicInfo didn't return an HttpResponse object. It returned None instead.
2016-09-05 11:51:28,816 [Thread-3:139757289719552] [django.request:256] [base:handle_uncaught_exception] [ERROR]- Internal Server Error: /AddBasicInfo/
Traceback (most recent call last):
  File "/usr/local/lib/python2.7/dist-packages/django/core/handlers/base.py", line 151, in get_response
    % (callback.__module__, view_name))
ValueError: The view website.views.AddBasicInfo didn't return an HttpResponse object. It returned None instead.
2016-09-05 12:13:50,197 [Thread-3:140689405601536] [django.request:256] [base:handle_uncaught_exception] [ERROR]- Internal Server Error: /AddBasicInfo/
Traceback (most recent call last):
  File "/usr/local/lib/python2.7/dist-packages/django/core/handlers/base.py", line 151, in get_response
    % (callback.__module__, view_name))
ValueError: The view website.views.AddBasicInfo didn't return an HttpResponse object. It returned None instead.
2016-09-05 12:14:48,700 [Thread-3:140421487191808] [django.request:256] [base:handle_uncaught_exception] [ERROR]- Internal Server Error: /AddBasicInfo/
Traceback (most recent call last):
  File "/usr/local/lib/python2.7/dist-packages/django/core/handlers/base.py", line 151, in get_response
    % (callback.__module__, view_name))
ValueError: The view website.views.AddBasicInfo didn't return an HttpResponse object. It returned None instead.
2016-09-05 12:16:30,952 [Thread-3:140347717375744] [django.request:256] [base:handle_uncaught_exception] [ERROR]- Internal Server Error: /AddBasicInfo/
Traceback (most recent call last):
  File "/usr/local/lib/python2.7/dist-packages/django/core/handlers/base.py", line 151, in get_response
    % (callback.__module__, view_name))
ValueError: The view website.views.AddBasicInfo didn't return an HttpResponse object. It returned None instead.
2016-09-05 17:24:33,217 [Thread-3:139668740937472] [django.request:256] [base:handle_uncaught_exception] [ERROR]- Internal Server Error: /AddBasicInfo/
Traceback (most recent call last):
  File "/usr/local/lib/python2.7/dist-packages/django/core/handlers/base.py", line 151, in get_response
    % (callback.__module__, view_name))
ValueError: The view website.views.AddBasicInfo didn't return an HttpResponse object. It returned None instead.
2016-09-05 17:25:07,848 [Thread-3:140264798586624] [django.request:256] [base:handle_uncaught_exception] [ERROR]- Internal Server Error: /AddBasicInfo/
Traceback (most recent call last):
  File "/usr/local/lib/python2.7/dist-packages/django/core/handlers/base.py", line 151, in get_response
    % (callback.__module__, view_name))
ValueError: The view website.views.AddBasicInfo didn't return an HttpResponse object. It returned None instead.
2016-09-05 17:26:17,118 [Thread-2:139968018118400] [django.request:256] [base:handle_uncaught_exception] [ERROR]- Internal Server Error: /AddBasicInfo/
Traceback (most recent call last):
  File "/usr/local/lib/python2.7/dist-packages/django/core/handlers/base.py", line 119, in get_response
    resolver_match = resolver.resolve(request.path_info)
  File "/usr/local/lib/python2.7/dist-packages/django/core/urlresolvers.py", line 365, in resolve
    for pattern in self.url_patterns:
  File "/usr/local/lib/python2.7/dist-packages/django/core/urlresolvers.py", line 401, in url_patterns
    patterns = getattr(self.urlconf_module, "urlpatterns", self.urlconf_module)
  File "/usr/local/lib/python2.7/dist-packages/django/core/urlresolvers.py", line 395, in urlconf_module
    self._urlconf_module = import_module(self.urlconf_name)
  File "/usr/lib/python2.7/importlib/__init__.py", line 37, in import_module
    __import__(name)
  File "/home/zzj/PycharmProjects/VOAM/VOAM/urls.py", line 17, in <module>
    from website.views import Index,AddVideoDevice,AddBasicInfo
  File "/home/zzj/PycharmProjects/VOAM/website/views.py", line 54
    elif devicegroup != 0:
       ^
SyntaxError: invalid syntax
2016-09-05 17:30:46,603 [Thread-5:139968018118400] [django.request:256] [base:handle_uncaught_exception] [ERROR]- Internal Server Error: /AddBasicInfo/
Traceback (most recent call last):
  File "/usr/local/lib/python2.7/dist-packages/django/core/handlers/base.py", line 151, in get_response
    % (callback.__module__, view_name))
ValueError: The view website.views.AddBasicInfo didn't return an HttpResponse object. It returned None instead.
2016-09-05 17:33:26,174 [Thread-3:139731123828480] [django.request:256] [base:handle_uncaught_exception] [ERROR]- Internal Server Error: /AddBasicInfo/
Traceback (most recent call last):
  File "/usr/local/lib/python2.7/dist-packages/django/core/handlers/base.py", line 151, in get_response
    % (callback.__module__, view_name))
ValueError: The view website.views.AddBasicInfo didn't return an HttpResponse object. It returned None instead.
2016-09-05 17:35:33,892 [Thread-3:139812047648512] [django.request:256] [base:handle_uncaught_exception] [ERROR]- Internal Server Error: /AddBasicInfo/
Traceback (most recent call last):
  File "/usr/local/lib/python2.7/dist-packages/django/core/handlers/base.py", line 151, in get_response
    % (callback.__module__, view_name))
ValueError: The view website.views.AddBasicInfo didn't return an HttpResponse object. It returned None instead.
2016-09-05 19:14:46,507 [Thread-3:123145310715904] [django.request:170] [base:get_response] [WARNING]- Not Found: /favicon.ico
2016-09-05 19:14:46,540 [Thread-4:123145310715904] [django.request:170] [base:get_response] [WARNING]- Not Found: /favicon.ico
2016-09-05 19:14:52,308 [Thread-5:123145310715904] [django.request:256] [base:handle_uncaught_exception] [ERROR]- Internal Server Error: /AddBasicInfo/
Traceback (most recent call last):
  File "/Library/Python/2.7/site-packages/Django-1.8.9-py2.7.egg/django/core/handlers/base.py", line 151, in get_response
    % (callback.__module__, view_name))
ValueError: The view website.views.AddBasicInfo didn't return an HttpResponse object. It returned None instead.
2016-09-05 19:19:43,559 [Thread-3:123145310715904] [django.request:256] [base:handle_uncaught_exception] [ERROR]- Internal Server Error: /AddBasicInfo/
Traceback (most recent call last):
  File "/Library/Python/2.7/site-packages/Django-1.8.9-py2.7.egg/django/core/handlers/base.py", line 151, in get_response
    % (callback.__module__, view_name))
ValueError: The view website.views.AddBasicInfo didn't return an HttpResponse object. It returned None instead.
2016-09-05 21:07:23,012 [Thread-2:123145310715904] [django.request:256] [base:handle_uncaught_exception] [ERROR]- Internal Server Error: /AddBasicInfo/
Traceback (most recent call last):
  File "/Library/Python/2.7/site-packages/Django-1.8.9-py2.7.egg/django/core/handlers/base.py", line 132, in get_response
    response = wrapped_callback(request, *callback_args, **callback_kwargs)
  File "/Users/ZZJMAC/PycharmProjects/VOAM/website/views.py", line 191, in AddBasicInfo
    DeviceType.objects.create(brandid=devicebrandid,name=devicetype)
  File "/Library/Python/2.7/site-packages/Django-1.8.9-py2.7.egg/django/db/models/manager.py", line 127, in manager_method
    return getattr(self.get_queryset(), name)(*args, **kwargs)
  File "/Library/Python/2.7/site-packages/Django-1.8.9-py2.7.egg/django/db/models/query.py", line 346, in create
    obj = self.model(**kwargs)
  File "/Library/Python/2.7/site-packages/Django-1.8.9-py2.7.egg/django/db/models/base.py", line 468, in __init__
    setattr(self, field.name, rel_obj)
  File "/Library/Python/2.7/site-packages/Django-1.8.9-py2.7.egg/django/db/models/fields/related.py", line 642, in __set__
    self.field.rel.to._meta.object_name,
ValueError: Cannot assign "u'1'": "DeviceType.brandid" must be a "DeviceBrand" instance.
2016-09-05 21:09:17,778 [Thread-3:123145310715904] [django.request:256] [base:handle_uncaught_exception] [ERROR]- Internal Server Error: /AddBasicInfo/
Traceback (most recent call last):
  File "/Library/Python/2.7/site-packages/Django-1.8.9-py2.7.egg/django/core/handlers/base.py", line 132, in get_response
    response = wrapped_callback(request, *callback_args, **callback_kwargs)
  File "/Users/ZZJMAC/PycharmProjects/VOAM/website/views.py", line 192, in AddBasicInfo
    DeviceType.objects.create(brandid=devicebrandid,name=devicetype)
  File "/Library/Python/2.7/site-packages/Django-1.8.9-py2.7.egg/django/db/models/manager.py", line 127, in manager_method
    return getattr(self.get_queryset(), name)(*args, **kwargs)
  File "/Library/Python/2.7/site-packages/Django-1.8.9-py2.7.egg/django/db/models/query.py", line 346, in create
    obj = self.model(**kwargs)
  File "/Library/Python/2.7/site-packages/Django-1.8.9-py2.7.egg/django/db/models/base.py", line 468, in __init__
    setattr(self, field.name, rel_obj)
  File "/Library/Python/2.7/site-packages/Django-1.8.9-py2.7.egg/django/db/models/fields/related.py", line 642, in __set__
    self.field.rel.to._meta.object_name,
ValueError: Cannot assign "u'1'": "DeviceType.brandid" must be a "DeviceBrand" instance.
2016-09-05 21:12:08,973 [Thread-2:123145310715904] [django.request:256] [base:handle_uncaught_exception] [ERROR]- Internal Server Error: /AddBasicInfo/
Traceback (most recent call last):
  File "/Library/Python/2.7/site-packages/Django-1.8.9-py2.7.egg/django/core/handlers/base.py", line 132, in get_response
    response = wrapped_callback(request, *callback_args, **callback_kwargs)
  File "/Users/ZZJMAC/PycharmProjects/VOAM/website/views.py", line 190, in AddBasicInfo
    result = DeviceType.objects.filter(name=devicetype,brandid_id=devicebrandid).count()
  File "/Library/Python/2.7/site-packages/Django-1.8.9-py2.7.egg/django/db/models/manager.py", line 127, in manager_method
    return getattr(self.get_queryset(), name)(*args, **kwargs)
  File "/Library/Python/2.7/site-packages/Django-1.8.9-py2.7.egg/django/db/models/query.py", line 679, in filter
    return self._filter_or_exclude(False, *args, **kwargs)
  File "/Library/Python/2.7/site-packages/Django-1.8.9-py2.7.egg/django/db/models/query.py", line 697, in _filter_or_exclude
    clone.query.add_q(Q(*args, **kwargs))
  File "/Library/Python/2.7/site-packages/Django-1.8.9-py2.7.egg/django/db/models/sql/query.py", line 1310, in add_q
    clause, require_inner = self._add_q(where_part, self.used_aliases)
  File "/Library/Python/2.7/site-packages/Django-1.8.9-py2.7.egg/django/db/models/sql/query.py", line 1338, in _add_q
    allow_joins=allow_joins, split_subq=split_subq,
  File "/Library/Python/2.7/site-packages/Django-1.8.9-py2.7.egg/django/db/models/sql/query.py", line 1200, in build_filter
    lookups, value)
  File "/Library/Python/2.7/site-packages/Django-1.8.9-py2.7.egg/django/db/models/fields/related.py", line 1761, in get_lookup_constraint
    lookup_class(target.get_col(alias, source), val), AND)
  File "/Library/Python/2.7/site-packages/Django-1.8.9-py2.7.egg/django/db/models/lookups.py", line 105, in __init__
    self.rhs = self.get_prep_lookup()
  File "/Library/Python/2.7/site-packages/Django-1.8.9-py2.7.egg/django/db/models/lookups.py", line 143, in get_prep_lookup
    return self.lhs.output_field.get_prep_lookup(self.lookup_name, self.rhs)
  File "/Library/Python/2.7/site-packages/Django-1.8.9-py2.7.egg/django/db/models/fields/__init__.py", line 727, in get_prep_lookup
    return self.get_prep_value(value)
  File "/Library/Python/2.7/site-packages/Django-1.8.9-py2.7.egg/django/db/models/fields/__init__.py", line 985, in get_prep_value
    return int(value)
ValueError: invalid literal for int() with base 10: ''
2016-09-05 23:56:29,866 [Thread-6:123145310715904] [django.request:256] [base:handle_uncaught_exception] [ERROR]- Internal Server Error: /
Traceback (most recent call last):
  File "/Library/Python/2.7/site-packages/Django-1.8.9-py2.7.egg/django/core/handlers/base.py", line 132, in get_response
    response = wrapped_callback(request, *callback_args, **callback_kwargs)
  File "/Users/ZZJMAC/PycharmProjects/VOAM/website/views.py", line 10, in Index
    good_serverlist = ServerHostDevice.objects.filter()
AttributeError: type object 'ServerHostDevice' has no attribute 'objects'
2016-09-05 23:57:35,046 [Thread-7:123145310715904] [django.request:256] [base:handle_uncaught_exception] [ERROR]- Internal Server Error: /
Traceback (most recent call last):
  File "/Library/Python/2.7/site-packages/Django-1.8.9-py2.7.egg/django/core/handlers/base.py", line 132, in get_response
    response = wrapped_callback(request, *callback_args, **callback_kwargs)
  File "/Users/ZZJMAC/PycharmProjects/VOAM/website/views.py", line 10, in Index
    good_serverlist = DeviceGroup.objects.all()
AttributeError: type object 'ServerHostDevice' has no attribute 'objects'
2016-09-05 23:57:44,204 [Thread-2:123145310715904] [django.request:256] [base:handle_uncaught_exception] [ERROR]- Internal Server Error: /
Traceback (most recent call last):
  File "/Library/Python/2.7/site-packages/Django-1.8.9-py2.7.egg/django/core/handlers/base.py", line 151, in get_response
    % (callback.__module__, view_name))
ValueError: The view website.views.Index didn't return an HttpResponse object. It returned None instead.
2016-09-06 09:34:22,451 [Thread-78:139850535827200] [django.request:256] [base:handle_uncaught_exception] [ERROR]- Internal Server Error: /AddBasicInfo/
Traceback (most recent call last):
  File "/usr/local/lib/python2.7/dist-packages/django/core/handlers/base.py", line 132, in get_response
    response = wrapped_callback(request, *callback_args, **callback_kwargs)
  File "/home/zzj/PycharmProjects/VOAM/website/views.py", line 220, in AddBasicInfo
    'devicetypeform': devicetypeform, 'devicebrandid': devicebrandid})
  File "/usr/local/lib/python2.7/dist-packages/django/shortcuts.py", line 39, in render_to_response
    content = loader.render_to_string(template_name, context, using=using)
  File "/usr/local/lib/python2.7/dist-packages/django/template/loader.py", line 99, in render_to_string
    return template.render(context, request)
  File "/usr/local/lib/python2.7/dist-packages/django/template/backends/django.py", line 74, in render
    return self.template.render(context)
  File "/usr/local/lib/python2.7/dist-packages/django/template/base.py", line 210, in render
    return self._render(context)
  File "/usr/local/lib/python2.7/dist-packages/django/template/base.py", line 202, in _render
    return self.nodelist.render(context)
  File "/usr/local/lib/python2.7/dist-packages/django/template/base.py", line 905, in render
    bit = self.render_node(node, context)
  File "/usr/local/lib/python2.7/dist-packages/django/template/debug.py", line 79, in render_node
    return node.render(context)
  File "/usr/local/lib/python2.7/dist-packages/django/template/loader_tags.py", line 135, in render
    return compiled_parent._render(context)
  File "/usr/local/lib/python2.7/dist-packages/django/template/base.py", line 202, in _render
    return self.nodelist.render(context)
  File "/usr/local/lib/python2.7/dist-packages/django/template/base.py", line 905, in render
    bit = self.render_node(node, context)
  File "/usr/local/lib/python2.7/dist-packages/django/template/debug.py", line 79, in render_node
    return node.render(context)
  File "/usr/local/lib/python2.7/dist-packages/django/template/loader_tags.py", line 65, in render
    result = block.nodelist.render(context)
  File "/usr/local/lib/python2.7/dist-packages/django/template/base.py", line 905, in render
    bit = self.render_node(node, context)
  File "/usr/local/lib/python2.7/dist-packages/django/template/debug.py", line 79, in render_node
    return node.render(context)
  File "/usr/local/lib/python2.7/dist-packages/django/template/defaulttags.py", line 162, in render
    len_values = len(values)
  File "/usr/local/lib/python2.7/dist-packages/django/db/models/query.py", line 144, in __len__
    self._fetch_all()
  File "/usr/local/lib/python2.7/dist-packages/django/db/models/query.py", line 965, in _fetch_all
    self._result_cache = list(self.iterator())
  File "/usr/local/lib/python2.7/dist-packages/django/db/models/query.py", line 238, in iterator
    results = compiler.execute_sql()
  File "/usr/local/lib/python2.7/dist-packages/django/db/models/sql/compiler.py", line 838, in execute_sql
    cursor = self.connection.cursor()
  File "/usr/local/lib/python2.7/dist-packages/django/db/backends/base/base.py", line 162, in cursor
    cursor = self.make_debug_cursor(self._cursor())
  File "/usr/local/lib/python2.7/dist-packages/django/db/backends/base/base.py", line 135, in _cursor
    self.ensure_connection()
  File "/usr/local/lib/python2.7/dist-packages/django/db/backends/base/base.py", line 130, in ensure_connection
    self.connect()
  File "/usr/local/lib/python2.7/dist-packages/django/db/utils.py", line 98, in __exit__
    six.reraise(dj_exc_type, dj_exc_value, traceback)
  File "/usr/local/lib/python2.7/dist-packages/django/db/backends/base/base.py", line 130, in ensure_connection
    self.connect()
  File "/usr/local/lib/python2.7/dist-packages/django/db/backends/base/base.py", line 119, in connect
    self.connection = self.get_new_connection(conn_params)
  File "/usr/local/lib/python2.7/dist-packages/django/db/backends/mysql/base.py", line 276, in get_new_connection
    conn = Database.connect(**conn_params)
  File "/usr/lib/python2.7/dist-packages/MySQLdb/__init__.py", line 81, in Connect
    return Connection(*args, **kwargs)
  File "/usr/lib/python2.7/dist-packages/MySQLdb/connections.py", line 239, in __init__
    self.set_character_set(charset)
  File "/usr/lib/python2.7/dist-packages/MySQLdb/connections.py", line 345, in set_character_set
    super(Connection, self).set_character_set(charset)
OperationalError: (2013, 'Lost connection to MySQL server during query')
2016-09-06 09:34:45,993 [Thread-79:139850545006336] [django.request:256] [base:handle_uncaught_exception] [ERROR]- Internal Server Error: /AddBasicInfo/
Traceback (most recent call last):
  File "/usr/local/lib/python2.7/dist-packages/django/core/handlers/base.py", line 132, in get_response
    response = wrapped_callback(request, *callback_args, **callback_kwargs)
  File "/home/zzj/PycharmProjects/VOAM/website/views.py", line 220, in AddBasicInfo
    'devicetypeform': devicetypeform, 'devicebrandid': devicebrandid})
  File "/usr/local/lib/python2.7/dist-packages/django/shortcuts.py", line 39, in render_to_response
    content = loader.render_to_string(template_name, context, using=using)
  File "/usr/local/lib/python2.7/dist-packages/django/template/loader.py", line 99, in render_to_string
    return template.render(context, request)
  File "/usr/local/lib/python2.7/dist-packages/django/template/backends/django.py", line 74, in render
    return self.template.render(context)
  File "/usr/local/lib/python2.7/dist-packages/django/template/base.py", line 210, in render
    return self._render(context)
  File "/usr/local/lib/python2.7/dist-packages/django/template/base.py", line 202, in _render
    return self.nodelist.render(context)
  File "/usr/local/lib/python2.7/dist-packages/django/template/base.py", line 905, in render
    bit = self.render_node(node, context)
  File "/usr/local/lib/python2.7/dist-packages/django/template/debug.py", line 79, in render_node
    return node.render(context)
  File "/usr/local/lib/python2.7/dist-packages/django/template/loader_tags.py", line 135, in render
    return compiled_parent._render(context)
  File "/usr/local/lib/python2.7/dist-packages/django/template/base.py", line 202, in _render
    return self.nodelist.render(context)
  File "/usr/local/lib/python2.7/dist-packages/django/template/base.py", line 905, in render
    bit = self.render_node(node, context)
  File "/usr/local/lib/python2.7/dist-packages/django/template/debug.py", line 79, in render_node
    return node.render(context)
  File "/usr/local/lib/python2.7/dist-packages/django/template/loader_tags.py", line 65, in render
    result = block.nodelist.render(context)
  File "/usr/local/lib/python2.7/dist-packages/django/template/base.py", line 905, in render
    bit = self.render_node(node, context)
  File "/usr/local/lib/python2.7/dist-packages/django/template/debug.py", line 79, in render_node
    return node.render(context)
  File "/usr/local/lib/python2.7/dist-packages/django/template/defaulttags.py", line 162, in render
    len_values = len(values)
  File "/usr/local/lib/python2.7/dist-packages/django/db/models/query.py", line 144, in __len__
    self._fetch_all()
  File "/usr/local/lib/python2.7/dist-packages/django/db/models/query.py", line 965, in _fetch_all
    self._result_cache = list(self.iterator())
  File "/usr/local/lib/python2.7/dist-packages/django/db/models/query.py", line 238, in iterator
    results = compiler.execute_sql()
  File "/usr/local/lib/python2.7/dist-packages/django/db/models/sql/compiler.py", line 838, in execute_sql
    cursor = self.connection.cursor()
  File "/usr/local/lib/python2.7/dist-packages/django/db/backends/base/base.py", line 162, in cursor
    cursor = self.make_debug_cursor(self._cursor())
  File "/usr/local/lib/python2.7/dist-packages/django/db/backends/base/base.py", line 135, in _cursor
    self.ensure_connection()
  File "/usr/local/lib/python2.7/dist-packages/django/db/backends/base/base.py", line 130, in ensure_connection
    self.connect()
  File "/usr/local/lib/python2.7/dist-packages/django/db/utils.py", line 98, in __exit__
    six.reraise(dj_exc_type, dj_exc_value, traceback)
  File "/usr/local/lib/python2.7/dist-packages/django/db/backends/base/base.py", line 130, in ensure_connection
    self.connect()
  File "/usr/local/lib/python2.7/dist-packages/django/db/backends/base/base.py", line 119, in connect
    self.connection = self.get_new_connection(conn_params)
  File "/usr/local/lib/python2.7/dist-packages/django/db/backends/mysql/base.py", line 276, in get_new_connection
    conn = Database.connect(**conn_params)
  File "/usr/lib/python2.7/dist-packages/MySQLdb/__init__.py", line 81, in Connect
    return Connection(*args, **kwargs)
  File "/usr/lib/python2.7/dist-packages/MySQLdb/connections.py", line 204, in __init__
    super(Connection, self).__init__(*args, **kwargs2)
OperationalError: (2013, "Lost connection to MySQL server at 'reading initial communication packet', system error: 104")
2016-09-06 09:37:17,430 [Thread-111:139850535827200] [django.request:256] [base:handle_uncaught_exception] [ERROR]- Internal Server Error: /AddBasicInfo/
Traceback (most recent call last):
  File "/usr/local/lib/python2.7/dist-packages/django/core/handlers/base.py", line 132, in get_response
    response = wrapped_callback(request, *callback_args, **callback_kwargs)
  File "/home/zzj/PycharmProjects/VOAM/website/views.py", line 220, in AddBasicInfo
    'devicetypeform': devicetypeform, 'devicebrandid': devicebrandid})
  File "/usr/local/lib/python2.7/dist-packages/django/shortcuts.py", line 39, in render_to_response
    content = loader.render_to_string(template_name, context, using=using)
  File "/usr/local/lib/python2.7/dist-packages/django/template/loader.py", line 99, in render_to_string
    return template.render(context, request)
  File "/usr/local/lib/python2.7/dist-packages/django/template/backends/django.py", line 74, in render
    return self.template.render(context)
  File "/usr/local/lib/python2.7/dist-packages/django/template/base.py", line 210, in render
    return self._render(context)
  File "/usr/local/lib/python2.7/dist-packages/django/template/base.py", line 202, in _render
    return self.nodelist.render(context)
  File "/usr/local/lib/python2.7/dist-packages/django/template/base.py", line 905, in render
    bit = self.render_node(node, context)
  File "/usr/local/lib/python2.7/dist-packages/django/template/debug.py", line 79, in render_node
    return node.render(context)
  File "/usr/local/lib/python2.7/dist-packages/django/template/loader_tags.py", line 135, in render
    return compiled_parent._render(context)
  File "/usr/local/lib/python2.7/dist-packages/django/template/base.py", line 202, in _render
    return self.nodelist.render(context)
  File "/usr/local/lib/python2.7/dist-packages/django/template/base.py", line 905, in render
    bit = self.render_node(node, context)
  File "/usr/local/lib/python2.7/dist-packages/django/template/debug.py", line 79, in render_node
    return node.render(context)
  File "/usr/local/lib/python2.7/dist-packages/django/template/loader_tags.py", line 65, in render
    result = block.nodelist.render(context)
  File "/usr/local/lib/python2.7/dist-packages/django/template/base.py", line 905, in render
    bit = self.render_node(node, context)
  File "/usr/local/lib/python2.7/dist-packages/django/template/debug.py", line 79, in render_node
    return node.render(context)
  File "/usr/local/lib/python2.7/dist-packages/django/template/defaulttags.py", line 162, in render
    len_values = len(values)
  File "/usr/local/lib/python2.7/dist-packages/django/db/models/query.py", line 144, in __len__
    self._fetch_all()
  File "/usr/local/lib/python2.7/dist-packages/django/db/models/query.py", line 965, in _fetch_all
    self._result_cache = list(self.iterator())
  File "/usr/local/lib/python2.7/dist-packages/django/db/models/query.py", line 238, in iterator
    results = compiler.execute_sql()
  File "/usr/local/lib/python2.7/dist-packages/django/db/models/sql/compiler.py", line 840, in execute_sql
    cursor.execute(sql, params)
  File "/usr/local/lib/python2.7/dist-packages/django/db/backends/utils.py", line 79, in execute
    return super(CursorDebugWrapper, self).execute(sql, params)
  File "/usr/local/lib/python2.7/dist-packages/django/db/backends/utils.py", line 64, in execute
    return self.cursor.execute(sql, params)
  File "/usr/local/lib/python2.7/dist-packages/django/db/utils.py", line 98, in __exit__
    six.reraise(dj_exc_type, dj_exc_value, traceback)
  File "/usr/local/lib/python2.7/dist-packages/django/db/backends/utils.py", line 64, in execute
    return self.cursor.execute(sql, params)
  File "/usr/local/lib/python2.7/dist-packages/django/db/backends/mysql/base.py", line 124, in execute
    return self.cursor.execute(query, args)
  File "/usr/lib/python2.7/dist-packages/MySQLdb/cursors.py", line 226, in execute
    self.errorhandler(self, exc, value)
  File "/usr/lib/python2.7/dist-packages/MySQLdb/connections.py", line 36, in defaulterrorhandler
    raise errorvalue
OperationalError: (2013, 'Lost connection to MySQL server during query')
2016-09-06 09:41:46,909 [Thread-145:139850535827200] [django.request:170] [base:get_response] [WARNING]- Not Found: /top.php
2016-09-06 09:49:32,451 [Thread-242:139850535827200] [django.request:256] [base:handle_uncaught_exception] [ERROR]- Internal Server Error: /AddBasicInfo/
Traceback (most recent call last):
  File "/usr/local/lib/python2.7/dist-packages/django/core/handlers/base.py", line 132, in get_response
    response = wrapped_callback(request, *callback_args, **callback_kwargs)
  File "/home/zzj/PycharmProjects/VOAM/website/views.py", line 220, in AddBasicInfo
    'devicetypeform': devicetypeform, 'devicebrandid': devicebrandid})
  File "/usr/local/lib/python2.7/dist-packages/django/shortcuts.py", line 39, in render_to_response
    content = loader.render_to_string(template_name, context, using=using)
  File "/usr/local/lib/python2.7/dist-packages/django/template/loader.py", line 99, in render_to_string
    return template.render(context, request)
  File "/usr/local/lib/python2.7/dist-packages/django/template/backends/django.py", line 74, in render
    return self.template.render(context)
  File "/usr/local/lib/python2.7/dist-packages/django/template/base.py", line 210, in render
    return self._render(context)
  File "/usr/local/lib/python2.7/dist-packages/django/template/base.py", line 202, in _render
    return self.nodelist.render(context)
  File "/usr/local/lib/python2.7/dist-packages/django/template/base.py", line 905, in render
    bit = self.render_node(node, context)
  File "/usr/local/lib/python2.7/dist-packages/django/template/debug.py", line 79, in render_node
    return node.render(context)
  File "/usr/local/lib/python2.7/dist-packages/django/template/loader_tags.py", line 135, in render
    return compiled_parent._render(context)
  File "/usr/local/lib/python2.7/dist-packages/django/template/base.py", line 202, in _render
    return self.nodelist.render(context)
  File "/usr/local/lib/python2.7/dist-packages/django/template/base.py", line 905, in render
    bit = self.render_node(node, context)
  File "/usr/local/lib/python2.7/dist-packages/django/template/debug.py", line 79, in render_node
    return node.render(context)
  File "/usr/local/lib/python2.7/dist-packages/django/template/loader_tags.py", line 65, in render
    result = block.nodelist.render(context)
  File "/usr/local/lib/python2.7/dist-packages/django/template/base.py", line 905, in render
    bit = self.render_node(node, context)
  File "/usr/local/lib/python2.7/dist-packages/django/template/debug.py", line 79, in render_node
    return node.render(context)
  File "/usr/local/lib/python2.7/dist-packages/django/template/defaulttags.py", line 162, in render
    len_values = len(values)
  File "/usr/local/lib/python2.7/dist-packages/django/db/models/query.py", line 144, in __len__
    self._fetch_all()
  File "/usr/local/lib/python2.7/dist-packages/django/db/models/query.py", line 965, in _fetch_all
    self._result_cache = list(self.iterator())
  File "/usr/local/lib/python2.7/dist-packages/django/db/models/query.py", line 238, in iterator
    results = compiler.execute_sql()
  File "/usr/local/lib/python2.7/dist-packages/django/db/models/sql/compiler.py", line 838, in execute_sql
    cursor = self.connection.cursor()
  File "/usr/local/lib/python2.7/dist-packages/django/db/backends/base/base.py", line 162, in cursor
    cursor = self.make_debug_cursor(self._cursor())
  File "/usr/local/lib/python2.7/dist-packages/django/db/backends/base/base.py", line 135, in _cursor
    self.ensure_connection()
  File "/usr/local/lib/python2.7/dist-packages/django/db/backends/base/base.py", line 130, in ensure_connection
    self.connect()
  File "/usr/local/lib/python2.7/dist-packages/django/db/backends/base/base.py", line 121, in connect
    self.init_connection_state()
  File "/usr/local/lib/python2.7/dist-packages/django/db/backends/mysql/base.py", line 287, in init_connection_state
    cursor.execute('SET SQL_AUTO_IS_NULL = 0')
  File "/usr/local/lib/python2.7/dist-packages/django/db/backends/utils.py", line 79, in execute
    return super(CursorDebugWrapper, self).execute(sql, params)
  File "/usr/local/lib/python2.7/dist-packages/django/db/backends/utils.py", line 64, in execute
    return self.cursor.execute(sql, params)
  File "/usr/local/lib/python2.7/dist-packages/django/db/utils.py", line 98, in __exit__
    six.reraise(dj_exc_type, dj_exc_value, traceback)
  File "/usr/local/lib/python2.7/dist-packages/django/db/backends/utils.py", line 62, in execute
    return self.cursor.execute(sql)
  File "/usr/local/lib/python2.7/dist-packages/django/db/backends/mysql/base.py", line 124, in execute
    return self.cursor.execute(query, args)
  File "/usr/lib/python2.7/dist-packages/MySQLdb/cursors.py", line 226, in execute
    self.errorhandler(self, exc, value)
  File "/usr/lib/python2.7/dist-packages/MySQLdb/connections.py", line 36, in defaulterrorhandler
    raise errorvalue
OperationalError: (2013, 'Lost connection to MySQL server during query')
2016-09-06 09:53:57,268 [Thread-256:139850535827200] [django.request:256] [base:handle_uncaught_exception] [ERROR]- Internal Server Error: /AddBasicInfo/
Traceback (most recent call last):
  File "/usr/local/lib/python2.7/dist-packages/django/core/handlers/base.py", line 132, in get_response
    response = wrapped_callback(request, *callback_args, **callback_kwargs)
  File "/home/zzj/PycharmProjects/VOAM/website/views.py", line 220, in AddBasicInfo
    'devicetypeform': devicetypeform, 'devicebrandid': devicebrandid})
  File "/usr/local/lib/python2.7/dist-packages/django/shortcuts.py", line 39, in render_to_response
    content = loader.render_to_string(template_name, context, using=using)
  File "/usr/local/lib/python2.7/dist-packages/django/template/loader.py", line 99, in render_to_string
    return template.render(context, request)
  File "/usr/local/lib/python2.7/dist-packages/django/template/backends/django.py", line 74, in render
    return self.template.render(context)
  File "/usr/local/lib/python2.7/dist-packages/django/template/base.py", line 210, in render
    return self._render(context)
  File "/usr/local/lib/python2.7/dist-packages/django/template/base.py", line 202, in _render
    return self.nodelist.render(context)
  File "/usr/local/lib/python2.7/dist-packages/django/template/base.py", line 905, in render
    bit = self.render_node(node, context)
  File "/usr/local/lib/python2.7/dist-packages/django/template/debug.py", line 79, in render_node
    return node.render(context)
  File "/usr/local/lib/python2.7/dist-packages/django/template/loader_tags.py", line 135, in render
    return compiled_parent._render(context)
  File "/usr/local/lib/python2.7/dist-packages/django/template/base.py", line 202, in _render
    return self.nodelist.render(context)
  File "/usr/local/lib/python2.7/dist-packages/django/template/base.py", line 905, in render
    bit = self.render_node(node, context)
  File "/usr/local/lib/python2.7/dist-packages/django/template/debug.py", line 79, in render_node
    return node.render(context)
  File "/usr/local/lib/python2.7/dist-packages/django/template/loader_tags.py", line 65, in render
    result = block.nodelist.render(context)
  File "/usr/local/lib/python2.7/dist-packages/django/template/base.py", line 905, in render
    bit = self.render_node(node, context)
  File "/usr/local/lib/python2.7/dist-packages/django/template/debug.py", line 79, in render_node
    return node.render(context)
  File "/usr/local/lib/python2.7/dist-packages/django/template/defaulttags.py", line 162, in render
    len_values = len(values)
  File "/usr/local/lib/python2.7/dist-packages/django/db/models/query.py", line 144, in __len__
    self._fetch_all()
  File "/usr/local/lib/python2.7/dist-packages/django/db/models/query.py", line 965, in _fetch_all
    self._result_cache = list(self.iterator())
  File "/usr/local/lib/python2.7/dist-packages/django/db/models/query.py", line 238, in iterator
    results = compiler.execute_sql()
  File "/usr/local/lib/python2.7/dist-packages/django/db/models/sql/compiler.py", line 838, in execute_sql
    cursor = self.connection.cursor()
  File "/usr/local/lib/python2.7/dist-packages/django/db/backends/base/base.py", line 162, in cursor
    cursor = self.make_debug_cursor(self._cursor())
  File "/usr/local/lib/python2.7/dist-packages/django/db/backends/base/base.py", line 135, in _cursor
    self.ensure_connection()
  File "/usr/local/lib/python2.7/dist-packages/django/db/backends/base/base.py", line 130, in ensure_connection
    self.connect()
  File "/usr/local/lib/python2.7/dist-packages/django/db/utils.py", line 98, in __exit__
    six.reraise(dj_exc_type, dj_exc_value, traceback)
  File "/usr/local/lib/python2.7/dist-packages/django/db/backends/base/base.py", line 130, in ensure_connection
    self.connect()
  File "/usr/local/lib/python2.7/dist-packages/django/db/backends/base/base.py", line 119, in connect
    self.connection = self.get_new_connection(conn_params)
  File "/usr/local/lib/python2.7/dist-packages/django/db/backends/mysql/base.py", line 276, in get_new_connection
    conn = Database.connect(**conn_params)
  File "/usr/lib/python2.7/dist-packages/MySQLdb/__init__.py", line 81, in Connect
    return Connection(*args, **kwargs)
  File "/usr/lib/python2.7/dist-packages/MySQLdb/connections.py", line 204, in __init__
    super(Connection, self).__init__(*args, **kwargs2)
OperationalError: (2013, "Lost connection to MySQL server at 'reading initial communication packet', system error: 104")
2016-09-06 10:54:41,408 [Thread-4:140426721515264] [django.request:256] [base:handle_uncaught_exception] [ERROR]- Internal Server Error: /AddBasicInfo/
Traceback (most recent call last):
  File "/usr/local/lib/python2.7/dist-packages/django/core/handlers/base.py", line 132, in get_response
    response = wrapped_callback(request, *callback_args, **callback_kwargs)
  File "/home/zzj/PycharmProjects/VOAM/website/views.py", line 180, in AddBasicInfo
    'devicetypelist': devicetype_list})
  File "/usr/local/lib/python2.7/dist-packages/django/shortcuts.py", line 39, in render_to_response
    content = loader.render_to_string(template_name, context, using=using)
  File "/usr/local/lib/python2.7/dist-packages/django/template/loader.py", line 99, in render_to_string
    return template.render(context, request)
  File "/usr/local/lib/python2.7/dist-packages/django/template/backends/django.py", line 74, in render
    return self.template.render(context)
  File "/usr/local/lib/python2.7/dist-packages/django/template/base.py", line 210, in render
    return self._render(context)
  File "/usr/local/lib/python2.7/dist-packages/django/template/base.py", line 202, in _render
    return self.nodelist.render(context)
  File "/usr/local/lib/python2.7/dist-packages/django/template/base.py", line 905, in render
    bit = self.render_node(node, context)
  File "/usr/local/lib/python2.7/dist-packages/django/template/debug.py", line 79, in render_node
    return node.render(context)
  File "/usr/local/lib/python2.7/dist-packages/django/template/loader_tags.py", line 135, in render
    return compiled_parent._render(context)
  File "/usr/local/lib/python2.7/dist-packages/django/template/base.py", line 202, in _render
    return self.nodelist.render(context)
  File "/usr/local/lib/python2.7/dist-packages/django/template/base.py", line 905, in render
    bit = self.render_node(node, context)
  File "/usr/local/lib/python2.7/dist-packages/django/template/debug.py", line 79, in render_node
    return node.render(context)
  File "/usr/local/lib/python2.7/dist-packages/django/template/loader_tags.py", line 65, in render
    result = block.nodelist.render(context)
  File "/usr/local/lib/python2.7/dist-packages/django/template/base.py", line 905, in render
    bit = self.render_node(node, context)
  File "/usr/local/lib/python2.7/dist-packages/django/template/debug.py", line 79, in render_node
    return node.render(context)
  File "/usr/local/lib/python2.7/dist-packages/django/template/defaulttags.py", line 162, in render
    len_values = len(values)
  File "/usr/local/lib/python2.7/dist-packages/django/db/models/query.py", line 144, in __len__
    self._fetch_all()
  File "/usr/local/lib/python2.7/dist-packages/django/db/models/query.py", line 965, in _fetch_all
    self._result_cache = list(self.iterator())
  File "/usr/local/lib/python2.7/dist-packages/django/db/models/query.py", line 238, in iterator
    results = compiler.execute_sql()
  File "/usr/local/lib/python2.7/dist-packages/django/db/models/sql/compiler.py", line 840, in execute_sql
    cursor.execute(sql, params)
  File "/usr/local/lib/python2.7/dist-packages/django/db/backends/utils.py", line 79, in execute
    return super(CursorDebugWrapper, self).execute(sql, params)
  File "/usr/local/lib/python2.7/dist-packages/django/db/backends/utils.py", line 64, in execute
    return self.cursor.execute(sql, params)
  File "/usr/local/lib/python2.7/dist-packages/django/db/utils.py", line 98, in __exit__
    six.reraise(dj_exc_type, dj_exc_value, traceback)
  File "/usr/local/lib/python2.7/dist-packages/django/db/backends/utils.py", line 64, in execute
    return self.cursor.execute(sql, params)
  File "/usr/local/lib/python2.7/dist-packages/django/db/backends/mysql/base.py", line 124, in execute
    return self.cursor.execute(query, args)
  File "/usr/lib/python2.7/dist-packages/MySQLdb/cursors.py", line 226, in execute
    self.errorhandler(self, exc, value)
  File "/usr/lib/python2.7/dist-packages/MySQLdb/connections.py", line 36, in defaulterrorhandler
    raise errorvalue
OperationalError: (2013, 'Lost connection to MySQL server during query')
2016-09-06 10:55:56,220 [Thread-18:140426614916864] [django.request:256] [base:handle_uncaught_exception] [ERROR]- Internal Server Error: /AddBasicInfo/
Traceback (most recent call last):
  File "/usr/local/lib/python2.7/dist-packages/django/core/handlers/base.py", line 132, in get_response
    response = wrapped_callback(request, *callback_args, **callback_kwargs)
  File "/home/zzj/PycharmProjects/VOAM/website/views.py", line 166, in AddBasicInfo
    result = VideoDirection.objects.filter(name=videodirection).count()
  File "/usr/local/lib/python2.7/dist-packages/django/db/models/query.py", line 318, in count
    return self.query.get_count(using=self.db)
  File "/usr/local/lib/python2.7/dist-packages/django/db/models/sql/query.py", line 466, in get_count
    number = obj.get_aggregation(using, ['__count'])['__count']
  File "/usr/local/lib/python2.7/dist-packages/django/db/models/sql/query.py", line 447, in get_aggregation
    result = compiler.execute_sql(SINGLE)
  File "/usr/local/lib/python2.7/dist-packages/django/db/models/sql/compiler.py", line 838, in execute_sql
    cursor = self.connection.cursor()
  File "/usr/local/lib/python2.7/dist-packages/django/db/backends/base/base.py", line 162, in cursor
    cursor = self.make_debug_cursor(self._cursor())
  File "/usr/local/lib/python2.7/dist-packages/django/db/backends/base/base.py", line 135, in _cursor
    self.ensure_connection()
  File "/usr/local/lib/python2.7/dist-packages/django/db/backends/base/base.py", line 130, in ensure_connection
    self.connect()
  File "/usr/local/lib/python2.7/dist-packages/django/db/utils.py", line 98, in __exit__
    six.reraise(dj_exc_type, dj_exc_value, traceback)
  File "/usr/local/lib/python2.7/dist-packages/django/db/backends/base/base.py", line 130, in ensure_connection
    self.connect()
  File "/usr/local/lib/python2.7/dist-packages/django/db/backends/base/base.py", line 119, in connect
    self.connection = self.get_new_connection(conn_params)
  File "/usr/local/lib/python2.7/dist-packages/django/db/backends/mysql/base.py", line 276, in get_new_connection
    conn = Database.connect(**conn_params)
  File "/usr/lib/python2.7/dist-packages/MySQLdb/__init__.py", line 81, in Connect
    return Connection(*args, **kwargs)
  File "/usr/lib/python2.7/dist-packages/MySQLdb/connections.py", line 204, in __init__
    super(Connection, self).__init__(*args, **kwargs2)
OperationalError: (2013, "Lost connection to MySQL server at 'reading initial communication packet', system error: 104")
2016-09-06 11:24:51,936 [Thread-69:140426623309568] [django.request:170] [base:get_response] [WARNING]- Not Found: /AddVideo
2016-09-06 17:18:42,669 [Thread-44:140114825139968] [django.request:256] [base:handle_uncaught_exception] [ERROR]- Internal Server Error: /AddVideoDevice/
Traceback (most recent call last):
  File "/usr/local/lib/python2.7/dist-packages/django/core/handlers/base.py", line 132, in get_response
    response = wrapped_callback(request, *callback_args, **callback_kwargs)
  File "/home/zzj/PycharmProjects/VOAM/website/views.py", line 367, in AddVideoDevice
    form = AddVideoDevice(request.POST)
  File "/home/zzj/PycharmProjects/VOAM/website/views.py", line 366, in AddVideoDevice
    if request.method == 'POST':
AttributeError: 'QueryDict' object has no attribute 'method'
2016-09-06 17:35:32,541 [Thread-2:139775174784768] [django.request:256] [base:handle_uncaught_exception] [ERROR]- Internal Server Error: /AddVideoDevice/
Traceback (most recent call last):
  File "/usr/local/lib/python2.7/dist-packages/django/core/handlers/base.py", line 132, in get_response
    response = wrapped_callback(request, *callback_args, **callback_kwargs)
  File "/home/zzj/PycharmProjects/VOAM/website/views.py", line 367, in AddVideoDevice
    form = AddVideoDevice(request.POST)
  File "/home/zzj/PycharmProjects/VOAM/website/views.py", line 366, in AddVideoDevice
    if request.method == 'POST':
AttributeError: 'QueryDict' object has no attribute 'method'
2016-09-07 00:33:46,392 [Thread-2:140563847456512] [django.request:256] [base:handle_uncaught_exception] [ERROR]- Internal Server Error: /AddVideoDevice/
Traceback (most recent call last):
  File "/usr/local/lib/python2.7/dist-packages/django/core/handlers/base.py", line 119, in get_response
    resolver_match = resolver.resolve(request.path_info)
  File "/usr/local/lib/python2.7/dist-packages/django/core/urlresolvers.py", line 365, in resolve
    for pattern in self.url_patterns:
  File "/usr/local/lib/python2.7/dist-packages/django/core/urlresolvers.py", line 401, in url_patterns
    patterns = getattr(self.urlconf_module, "urlpatterns", self.urlconf_module)
  File "/usr/local/lib/python2.7/dist-packages/django/core/urlresolvers.py", line 395, in urlconf_module
    self._urlconf_module = import_module(self.urlconf_name)
  File "/usr/lib/python2.7/importlib/__init__.py", line 37, in import_module
    __import__(name)
  File "/home/zzj/PycharmProjects/VOAM/VOAM/urls.py", line 17, in <module>
    from website.views import Index,AddVideoDevice,AddBasicInfo
  File "/home/zzj/PycharmProjects/VOAM/website/views.py", line 5, in <module>
    from website.forms import AddVideoDeviceForm,AddDeviceStatusForm,AddDeviceGroupForm,AddDeviceRegionForm,AddVideoDirectionForm,AddVideoTypeForm,AddDeviceBrandForm,AddDeviceTypeForm
  File "/home/zzj/PycharmProjects/VOAM/website/forms.py", line 4, in <module>
    class AddVideoDeviceForm(forms.Form):
  File "/home/zzj/PycharmProjects/VOAM/website/forms.py", line 5, in AddVideoDeviceForm
    pid = forms.CharField(null=True)
  File "/usr/local/lib/python2.7/dist-packages/django/forms/fields.py", line 214, in __init__
    super(CharField, self).__init__(*args, **kwargs)
TypeError: __init__() got an unexpected keyword argument 'null'
2016-09-07 14:41:38,905 [Thread-7:139915240863488] [django.request:170] [base:get_response] [WARNING]- Not Found: /favicon.ico
2016-09-07 16:52:15,731 [Thread-44:139954395019008] [django.request:256] [base:handle_uncaught_exception] [ERROR]- Internal Server Error: /AddVideoDevice/
Traceback (most recent call last):
  File "/usr/local/lib/python2.7/dist-packages/django/core/handlers/base.py", line 132, in get_response
    response = wrapped_callback(request, *callback_args, **callback_kwargs)
  File "/home/zzj/PycharmProjects/VOAM/website/views.py", line 386, in AddVideoDevice
    VideoDevice.objects.create(pid=pid,name=name,group=group,region=region,direction=direction,vtype=vtype,ip=ip,username=username,password=password,gpslon=gpslon,gpswei=gpswei)
  File "/usr/local/lib/python2.7/dist-packages/django/db/models/manager.py", line 127, in manager_method
    return getattr(self.get_queryset(), name)(*args, **kwargs)
  File "/usr/local/lib/python2.7/dist-packages/django/db/models/query.py", line 346, in create
    obj = self.model(**kwargs)
  File "/usr/local/lib/python2.7/dist-packages/django/db/models/base.py", line 468, in __init__
    setattr(self, field.name, rel_obj)
  File "/usr/local/lib/python2.7/dist-packages/django/db/models/fields/related.py", line 642, in __set__
    self.field.rel.to._meta.object_name,
ValueError: Cannot assign "u'2'": "VideoDevice.group" must be a "DeviceGroup" instance.
2016-09-07 17:02:22,878 [Thread-3:140084972979968] [django.request:256] [base:handle_uncaught_exception] [ERROR]- Internal Server Error: /AddVideoDevice/
Traceback (most recent call last):
  File "/usr/local/lib/python2.7/dist-packages/django/core/handlers/base.py", line 132, in get_response
    response = wrapped_callback(request, *callback_args, **callback_kwargs)
  File "/home/zzj/PycharmProjects/VOAM/website/views.py", line 386, in AddVideoDevice
    VideoDevice.objects.create(pid=pid,name=name,group_id=group,region=region,direction=direction,vtype=vtype,ip=ip,username=username,password=password,gpslon=gpslon,gpswei=gpswei)
  File "/usr/local/lib/python2.7/dist-packages/django/db/models/manager.py", line 127, in manager_method
    return getattr(self.get_queryset(), name)(*args, **kwargs)
  File "/usr/local/lib/python2.7/dist-packages/django/db/models/query.py", line 346, in create
    obj = self.model(**kwargs)
  File "/usr/local/lib/python2.7/dist-packages/django/db/models/base.py", line 468, in __init__
    setattr(self, field.name, rel_obj)
  File "/usr/local/lib/python2.7/dist-packages/django/db/models/fields/related.py", line 642, in __set__
    self.field.rel.to._meta.object_name,
ValueError: Cannot assign "u'1'": "VideoDevice.region" must be a "DeviceRegion" instance.
2016-09-07 17:02:39,238 [Thread-5:139800666765056] [django.request:256] [base:handle_uncaught_exception] [ERROR]- Internal Server Error: /AddVideoDevice/
Traceback (most recent call last):
  File "/usr/local/lib/python2.7/dist-packages/django/core/handlers/base.py", line 132, in get_response
    response = wrapped_callback(request, *callback_args, **callback_kwargs)
  File "/home/zzj/PycharmProjects/VOAM/website/views.py", line 386, in AddVideoDevice
    VideoDevice.objects.create(pid=pid,name=name,groupid_id=group,region=region,direction=direction,vtype=vtype,ip=ip,username=username,password=password,gpslon=gpslon,gpswei=gpswei)
  File "/usr/local/lib/python2.7/dist-packages/django/db/models/manager.py", line 127, in manager_method
    return getattr(self.get_queryset(), name)(*args, **kwargs)
  File "/usr/local/lib/python2.7/dist-packages/django/db/models/query.py", line 346, in create
    obj = self.model(**kwargs)
  File "/usr/local/lib/python2.7/dist-packages/django/db/models/base.py", line 468, in __init__
    setattr(self, field.name, rel_obj)
  File "/usr/local/lib/python2.7/dist-packages/django/db/models/fields/related.py", line 642, in __set__
    self.field.rel.to._meta.object_name,
ValueError: Cannot assign "u'1'": "VideoDevice.region" must be a "DeviceRegion" instance.
2016-09-07 17:03:47,561 [Thread-3:140139548374784] [django.request:256] [base:handle_uncaught_exception] [ERROR]- Internal Server Error: /AddVideoDevice/
Traceback (most recent call last):
  File "/usr/local/lib/python2.7/dist-packages/django/core/handlers/base.py", line 132, in get_response
    response = wrapped_callback(request, *callback_args, **callback_kwargs)
  File "/home/zzj/PycharmProjects/VOAM/website/views.py", line 386, in AddVideoDevice
    VideoDevice.objects.create(pid=pid,name=name,group_id=group,region=region,direction=direction,vtype=vtype,ip=ip,username=username,password=password,gpslon=gpslon,gpswei=gpswei)
  File "/usr/local/lib/python2.7/dist-packages/django/db/models/manager.py", line 127, in manager_method
    return getattr(self.get_queryset(), name)(*args, **kwargs)
  File "/usr/local/lib/python2.7/dist-packages/django/db/models/query.py", line 346, in create
    obj = self.model(**kwargs)
  File "/usr/local/lib/python2.7/dist-packages/django/db/models/base.py", line 468, in __init__
    setattr(self, field.name, rel_obj)
  File "/usr/local/lib/python2.7/dist-packages/django/db/models/fields/related.py", line 642, in __set__
    self.field.rel.to._meta.object_name,
ValueError: Cannot assign "u'1'": "VideoDevice.region" must be a "DeviceRegion" instance.
2016-09-07 17:11:28,484 [Thread-5:140516346107648] [django.request:256] [base:handle_uncaught_exception] [ERROR]- Internal Server Error: /AddVideoDevice/
Traceback (most recent call last):
  File "/usr/local/lib/python2.7/dist-packages/django/core/handlers/base.py", line 132, in get_response
    response = wrapped_callback(request, *callback_args, **callback_kwargs)
  File "/home/zzj/PycharmProjects/VOAM/website/views.py", line 386, in AddVideoDevice
    VideoDevice.objects.create(pid=pid,name=name,group_id=group,region_id=region,direction=direction,vtype_id=vtype,ip=ip,username=username,password=password,gpslon=gpslon,gpswei=gpswei)
  File "/usr/local/lib/python2.7/dist-packages/django/db/models/manager.py", line 127, in manager_method
    return getattr(self.get_queryset(), name)(*args, **kwargs)
  File "/usr/local/lib/python2.7/dist-packages/django/db/models/query.py", line 346, in create
    obj = self.model(**kwargs)
  File "/usr/local/lib/python2.7/dist-packages/django/db/models/base.py", line 468, in __init__
    setattr(self, field.name, rel_obj)
  File "/usr/local/lib/python2.7/dist-packages/django/db/models/fields/related.py", line 642, in __set__
    self.field.rel.to._meta.object_name,
ValueError: Cannot assign "u'1'": "VideoDevice.direction" must be a "VideoDirection" instance.
2016-09-07 17:22:28,341 [Thread-9:140516329322240] [django.request:256] [base:handle_uncaught_exception] [ERROR]- Internal Server Error: /AddVideoDevice/
Traceback (most recent call last):
  File "/usr/local/lib/python2.7/dist-packages/django/core/handlers/base.py", line 132, in get_response
    response = wrapped_callback(request, *callback_args, **callback_kwargs)
  File "/home/zzj/PycharmProjects/VOAM/website/views.py", line 386, in AddVideoDevice
    VideoDevice.objects.create(pid=pid,name=name,group_id=group,region_id=region,direction=direction,vtype_id=vtype,ip=ip,username=username,password=password,gpslon=gpslon,gpswei=gpswei)
  File "/usr/local/lib/python2.7/dist-packages/django/db/models/manager.py", line 127, in manager_method
    return getattr(self.get_queryset(), name)(*args, **kwargs)
  File "/usr/local/lib/python2.7/dist-packages/django/db/models/query.py", line 346, in create
    obj = self.model(**kwargs)
  File "/usr/local/lib/python2.7/dist-packages/django/db/models/base.py", line 468, in __init__
    setattr(self, field.name, rel_obj)
  File "/usr/local/lib/python2.7/dist-packages/django/db/models/fields/related.py", line 642, in __set__
    self.field.rel.to._meta.object_name,
ValueError: Cannot assign "u'1'": "VideoDevice.direction" must be a "VideoDirection" instance.
2016-09-08 09:54:42,337 [Thread-7:140264191350528] [django.request:170] [base:get_response] [WARNING]- Not Found: /favicon.ico
2016-09-08 09:54:46,668 [Thread-8:140264191350528] [django.request:256] [base:handle_uncaught_exception] [ERROR]- Internal Server Error: /AddVideoDevice/
Traceback (most recent call last):
  File "/usr/local/lib/python2.7/dist-packages/django/core/handlers/base.py", line 132, in get_response
    response = wrapped_callback(request, *callback_args, **callback_kwargs)
  File "/home/zzj/PycharmProjects/VOAM/website/views.py", line 386, in AddVideoDevice
    VideoDevice.objects.create(pid=pid,name=name,group_id=group,region_id=region,direction=direction,vtype_id=vtype,ip=ip,username=username,password=password,gpslon=gpslon,gpswei=gpswei)
  File "/usr/local/lib/python2.7/dist-packages/django/db/models/manager.py", line 127, in manager_method
    return getattr(self.get_queryset(), name)(*args, **kwargs)
  File "/usr/local/lib/python2.7/dist-packages/django/db/models/query.py", line 346, in create
    obj = self.model(**kwargs)
  File "/usr/local/lib/python2.7/dist-packages/django/db/models/base.py", line 468, in __init__
    setattr(self, field.name, rel_obj)
  File "/usr/local/lib/python2.7/dist-packages/django/db/models/fields/related.py", line 642, in __set__
    self.field.rel.to._meta.object_name,
ValueError: Cannot assign "u'1'": "VideoDevice.direction" must be a "VideoDirection" instance.
2016-09-08 10:29:11,228 [Thread-44:139669702432512] [django.request:256] [base:handle_uncaught_exception] [ERROR]- Internal Server Error: /AddVideoDevice/
Traceback (most recent call last):
  File "/usr/local/lib/python2.7/dist-packages/django/core/handlers/base.py", line 132, in get_response
    response = wrapped_callback(request, *callback_args, **callback_kwargs)
  File "/home/zzj/PycharmProjects/VOAM/website/views.py", line 386, in AddVideoDevice
    VideoDevice.objects.create(pid=pid,name=name,group_id=group,region_id=region,direction=direction,vtype_id=vtype,ip=ip,username=username,password=password,gpslon=gpslon,gpswei=gpswei)
  File "/usr/local/lib/python2.7/dist-packages/django/db/models/manager.py", line 127, in manager_method
    return getattr(self.get_queryset(), name)(*args, **kwargs)
  File "/usr/local/lib/python2.7/dist-packages/django/db/models/query.py", line 346, in create
    obj = self.model(**kwargs)
  File "/usr/local/lib/python2.7/dist-packages/django/db/models/base.py", line 468, in __init__
    setattr(self, field.name, rel_obj)
  File "/usr/local/lib/python2.7/dist-packages/django/db/models/fields/related.py", line 642, in __set__
    self.field.rel.to._meta.object_name,
ValueError: Cannot assign "u'1'": "VideoDevice.direction" must be a "VideoDirection" instance.
2016-09-08 15:59:30,788 [Thread-45:140616818222848] [django.request:256] [base:handle_uncaught_exception] [ERROR]- Internal Server Error: /AddVideoDevice/
Traceback (most recent call last):
  File "/usr/local/lib/python2.7/dist-packages/django/core/handlers/base.py", line 132, in get_response
    response = wrapped_callback(request, *callback_args, **callback_kwargs)
  File "/home/zzj/PycharmProjects/VOAM/website/views.py", line 387, in AddVideoDevice
    VideoDevice.objects.create(pid=pid,name=name,group_id=group,region_id=region,direction_id=direction,vtype_id=vtype,ip=ip,username=username,password=password,gpslon=gpslon,gpswei=gpswei)
  File "/usr/local/lib/python2.7/dist-packages/django/db/models/manager.py", line 127, in manager_method
    return getattr(self.get_queryset(), name)(*args, **kwargs)
  File "/usr/local/lib/python2.7/dist-packages/django/db/models/query.py", line 346, in create
    obj = self.model(**kwargs)
  File "/usr/local/lib/python2.7/dist-packages/django/db/models/base.py", line 480, in __init__
    raise TypeError("'%s' is an invalid keyword argument for this function" % list(kwargs)[0])
TypeError: 'vtype_id' is an invalid keyword argument for this function
2016-09-08 16:00:48,195 [Thread-3:140493641398016] [django.request:256] [base:handle_uncaught_exception] [ERROR]- Internal Server Error: /AddVideoDevice/
Traceback (most recent call last):
  File "/usr/local/lib/python2.7/dist-packages/django/core/handlers/base.py", line 132, in get_response
    response = wrapped_callback(request, *callback_args, **callback_kwargs)
  File "/home/zzj/PycharmProjects/VOAM/website/views.py", line 387, in AddVideoDevice
    VideoDevice.objects.create(pid=pid,name=name,groupid_id=group,regionid_id=region,directionid_id=direction,vtypeid_id=vtype,ip=ip,username=username,password=password,gpslon=gpslon,gpswei=gpswei)
  File "/usr/local/lib/python2.7/dist-packages/django/db/models/manager.py", line 127, in manager_method
    return getattr(self.get_queryset(), name)(*args, **kwargs)
  File "/usr/local/lib/python2.7/dist-packages/django/db/models/query.py", line 348, in create
    obj.save(force_insert=True, using=self.db)
  File "/usr/local/lib/python2.7/dist-packages/django/db/models/base.py", line 734, in save
    force_update=force_update, update_fields=update_fields)
  File "/usr/local/lib/python2.7/dist-packages/django/db/models/base.py", line 762, in save_base
    updated = self._save_table(raw, cls, force_insert, force_update, using, update_fields)
  File "/usr/local/lib/python2.7/dist-packages/django/db/models/base.py", line 846, in _save_table
    result = self._do_insert(cls._base_manager, using, fields, update_pk, raw)
  File "/usr/local/lib/python2.7/dist-packages/django/db/models/base.py", line 885, in _do_insert
    using=using, raw=raw)
  File "/usr/local/lib/python2.7/dist-packages/django/db/models/manager.py", line 127, in manager_method
    return getattr(self.get_queryset(), name)(*args, **kwargs)
  File "/usr/local/lib/python2.7/dist-packages/django/db/models/query.py", line 920, in _insert
    return query.get_compiler(using=using).execute_sql(return_id)
  File "/usr/local/lib/python2.7/dist-packages/django/db/models/sql/compiler.py", line 974, in execute_sql
    cursor.execute(sql, params)
  File "/usr/local/lib/python2.7/dist-packages/django/db/backends/utils.py", line 79, in execute
    return super(CursorDebugWrapper, self).execute(sql, params)
  File "/usr/local/lib/python2.7/dist-packages/django/db/backends/utils.py", line 64, in execute
    return self.cursor.execute(sql, params)
  File "/usr/local/lib/python2.7/dist-packages/django/db/backends/mysql/base.py", line 129, in execute
    six.reraise(utils.IntegrityError, utils.IntegrityError(*tuple(e.args)), sys.exc_info()[2])
  File "/usr/local/lib/python2.7/dist-packages/django/db/backends/mysql/base.py", line 124, in execute
    return self.cursor.execute(query, args)
  File "/usr/lib/python2.7/dist-packages/MySQLdb/cursors.py", line 226, in execute
    self.errorhandler(self, exc, value)
  File "/usr/lib/python2.7/dist-packages/MySQLdb/connections.py", line 36, in defaulterrorhandler
    raise errorvalue
IntegrityError: (1048, "Column 'brandid_id' cannot be null")
2016-09-08 16:09:49,170 [Thread-15:140635944249088] [django.request:256] [base:handle_uncaught_exception] [ERROR]- Internal Server Error: /AddVideoDevice/
Traceback (most recent call last):
  File "/usr/local/lib/python2.7/dist-packages/django/core/handlers/base.py", line 132, in get_response
    response = wrapped_callback(request, *callback_args, **callback_kwargs)
  File "/home/zzj/PycharmProjects/VOAM/website/views.py", line 389, in AddVideoDevice
    VideoDevice.objects.create(pid=pid,name=name,groupid_id=group,regionid_id=region,directionid_id=direction,vtypeid_id=vtype,ip=ip,username=username,password=password,gpslon=gpslon,gpswei=gpswei)
  File "/usr/local/lib/python2.7/dist-packages/django/db/models/manager.py", line 127, in manager_method
    return getattr(self.get_queryset(), name)(*args, **kwargs)
  File "/usr/local/lib/python2.7/dist-packages/django/db/models/query.py", line 348, in create
    obj.save(force_insert=True, using=self.db)
  File "/usr/local/lib/python2.7/dist-packages/django/db/models/base.py", line 734, in save
    force_update=force_update, update_fields=update_fields)
  File "/usr/local/lib/python2.7/dist-packages/django/db/models/base.py", line 762, in save_base
    updated = self._save_table(raw, cls, force_insert, force_update, using, update_fields)
  File "/usr/local/lib/python2.7/dist-packages/django/db/models/base.py", line 846, in _save_table
    result = self._do_insert(cls._base_manager, using, fields, update_pk, raw)
  File "/usr/local/lib/python2.7/dist-packages/django/db/models/base.py", line 885, in _do_insert
    using=using, raw=raw)
  File "/usr/local/lib/python2.7/dist-packages/django/db/models/manager.py", line 127, in manager_method
    return getattr(self.get_queryset(), name)(*args, **kwargs)
  File "/usr/local/lib/python2.7/dist-packages/django/db/models/query.py", line 920, in _insert
    return query.get_compiler(using=using).execute_sql(return_id)
  File "/usr/local/lib/python2.7/dist-packages/django/db/models/sql/compiler.py", line 974, in execute_sql
    cursor.execute(sql, params)
  File "/usr/local/lib/python2.7/dist-packages/django/db/backends/utils.py", line 79, in execute
    return super(CursorDebugWrapper, self).execute(sql, params)
  File "/usr/local/lib/python2.7/dist-packages/django/db/backends/utils.py", line 64, in execute
    return self.cursor.execute(sql, params)
  File "/usr/local/lib/python2.7/dist-packages/django/db/backends/mysql/base.py", line 129, in execute
    six.reraise(utils.IntegrityError, utils.IntegrityError(*tuple(e.args)), sys.exc_info()[2])
  File "/usr/local/lib/python2.7/dist-packages/django/db/backends/mysql/base.py", line 124, in execute
    return self.cursor.execute(query, args)
  File "/usr/lib/python2.7/dist-packages/MySQLdb/cursors.py", line 226, in execute
    self.errorhandler(self, exc, value)
  File "/usr/lib/python2.7/dist-packages/MySQLdb/connections.py", line 36, in defaulterrorhandler
    raise errorvalue
IntegrityError: (1048, "Column 'brandid_id' cannot be null")
2016-09-08 16:11:23,722 [Thread-22:140636035585792] [django.request:256] [base:handle_uncaught_exception] [ERROR]- Internal Server Error: /AddVideoDevice/
Traceback (most recent call last):
  File "/usr/local/lib/python2.7/dist-packages/django/core/handlers/base.py", line 132, in get_response
    response = wrapped_callback(request, *callback_args, **callback_kwargs)
  File "/home/zzj/PycharmProjects/VOAM/website/views.py", line 389, in AddVideoDevice
    VideoDevice.objects.create(pid=pid,name=name,groupid_id=group,regionid_id=region,directionid_id=direction,vtypeid_id=vtype,ip=ip,username=username,password=password,gpslon=gpslon,gpswei=gpswei)
  File "/usr/local/lib/python2.7/dist-packages/django/db/models/manager.py", line 127, in manager_method
    return getattr(self.get_queryset(), name)(*args, **kwargs)
  File "/usr/local/lib/python2.7/dist-packages/django/db/models/query.py", line 348, in create
    obj.save(force_insert=True, using=self.db)
  File "/usr/local/lib/python2.7/dist-packages/django/db/models/base.py", line 734, in save
    force_update=force_update, update_fields=update_fields)
  File "/usr/local/lib/python2.7/dist-packages/django/db/models/base.py", line 762, in save_base
    updated = self._save_table(raw, cls, force_insert, force_update, using, update_fields)
  File "/usr/local/lib/python2.7/dist-packages/django/db/models/base.py", line 846, in _save_table
    result = self._do_insert(cls._base_manager, using, fields, update_pk, raw)
  File "/usr/local/lib/python2.7/dist-packages/django/db/models/base.py", line 885, in _do_insert
    using=using, raw=raw)
  File "/usr/local/lib/python2.7/dist-packages/django/db/models/manager.py", line 127, in manager_method
    return getattr(self.get_queryset(), name)(*args, **kwargs)
  File "/usr/local/lib/python2.7/dist-packages/django/db/models/query.py", line 920, in _insert
    return query.get_compiler(using=using).execute_sql(return_id)
  File "/usr/local/lib/python2.7/dist-packages/django/db/models/sql/compiler.py", line 974, in execute_sql
    cursor.execute(sql, params)
  File "/usr/local/lib/python2.7/dist-packages/django/db/backends/utils.py", line 79, in execute
    return super(CursorDebugWrapper, self).execute(sql, params)
  File "/usr/local/lib/python2.7/dist-packages/django/db/backends/utils.py", line 64, in execute
    return self.cursor.execute(sql, params)
  File "/usr/local/lib/python2.7/dist-packages/django/db/backends/mysql/base.py", line 129, in execute
    six.reraise(utils.IntegrityError, utils.IntegrityError(*tuple(e.args)), sys.exc_info()[2])
  File "/usr/local/lib/python2.7/dist-packages/django/db/backends/mysql/base.py", line 124, in execute
    return self.cursor.execute(query, args)
  File "/usr/lib/python2.7/dist-packages/MySQLdb/cursors.py", line 226, in execute
    self.errorhandler(self, exc, value)
  File "/usr/lib/python2.7/dist-packages/MySQLdb/connections.py", line 36, in defaulterrorhandler
    raise errorvalue
IntegrityError: (1048, "Column 'brandid_id' cannot be null")
2016-09-08 16:12:28,200 [Thread-3:139657292515072] [django.request:256] [base:handle_uncaught_exception] [ERROR]- Internal Server Error: /AddVideoDevice/
Traceback (most recent call last):
  File "/usr/local/lib/python2.7/dist-packages/django/core/handlers/base.py", line 132, in get_response
    response = wrapped_callback(request, *callback_args, **callback_kwargs)
  File "/home/zzj/PycharmProjects/VOAM/website/views.py", line 389, in AddVideoDevice
    VideoDevice.objects.create(pid=pid,name=name,groupid_id=group,regionid_id=region,directionid_id=direction,vtypeid_id=vtype,ip=ip,username=username,password=password,gpslon=gpslon,gpswei=gpswei,brandid=brand,dtypeid=dtype)
  File "/usr/local/lib/python2.7/dist-packages/django/db/models/manager.py", line 127, in manager_method
    return getattr(self.get_queryset(), name)(*args, **kwargs)
  File "/usr/local/lib/python2.7/dist-packages/django/db/models/query.py", line 346, in create
    obj = self.model(**kwargs)
  File "/usr/local/lib/python2.7/dist-packages/django/db/models/base.py", line 468, in __init__
    setattr(self, field.name, rel_obj)
  File "/usr/local/lib/python2.7/dist-packages/django/db/models/fields/related.py", line 642, in __set__
    self.field.rel.to._meta.object_name,
ValueError: Cannot assign "u'1'": "VideoDevice.brandid" must be a "DeviceBrand" instance.
2016-09-08 16:41:53,154 [Thread-41:139793467963136] [django.request:170] [base:get_response] [WARNING]- Not Found: /ServerHost/1/
2016-09-08 18:56:05,592 [Thread-9:139991746860800] [django.request:170] [base:get_response] [WARNING]- Not Found: /VideoDevice/1/
2016-09-08 19:14:03,220 [Thread-2:140345058739968] [django.request:170] [base:get_response] [WARNING]- Not Found: /favicon.ico
2016-09-08 23:47:36,567 [Thread-48:140344817604352] [django.request:170] [base:get_response] [WARNING]- Not Found: /AddVideoDevice/remote.html
2016-09-09 09:01:19,761 [Thread-15:140361940047616] [django.request:256] [base:handle_uncaught_exception] [ERROR]- Internal Server Error: /UpdateVideoDevice/1/
Traceback (most recent call last):
  File "/usr/local/lib/python2.7/dist-packages/django/core/handlers/base.py", line 132, in get_response
    response = wrapped_callback(request, *callback_args, **callback_kwargs)
  File "/home/zzj/PycharmProjects/VOAM/website/views.py", line 401, in UpdateVideoDevice
    updatevideodevice = UpdateVideoDeviceForm()
NameError: global name 'UpdateVideoDeviceForm' is not defined
2016-09-09 09:04:56,120 [Thread-24:140361940047616] [django.request:256] [base:handle_uncaught_exception] [ERROR]- Internal Server Error: /UpdateVideoDevice/1/
Traceback (most recent call last):
  File "/usr/local/lib/python2.7/dist-packages/django/core/handlers/base.py", line 132, in get_response
    response = wrapped_callback(request, *callback_args, **callback_kwargs)
  File "/home/zzj/PycharmProjects/VOAM/website/views.py", line 401, in UpdateVideoDevice
    updatevideodevice = UpdateVideoDeviceForm()
NameError: global name 'UpdateVideoDeviceForm' is not defined
2016-09-09 09:06:19,964 [Thread-27:140361940047616] [django.request:256] [base:handle_uncaught_exception] [ERROR]- Internal Server Error: /UpdateVideoDevice/1/
Traceback (most recent call last):
  File "/usr/local/lib/python2.7/dist-packages/django/core/handlers/base.py", line 132, in get_response
    response = wrapped_callback(request, *callback_args, **callback_kwargs)
  File "/home/zzj/PycharmProjects/VOAM/website/views.py", line 401, in UpdateVideoDevice
    updatevideodevice = UpdateVideoDeviceForm()
NameError: global name 'UpdateVideoDeviceForm' is not defined
2016-09-09 09:11:24,413 [Thread-32:140361940047616] [django.request:256] [base:handle_uncaught_exception] [ERROR]- Internal Server Error: /UpdateVideoDevice/1/
Traceback (most recent call last):
  File "/usr/local/lib/python2.7/dist-packages/django/core/handlers/base.py", line 132, in get_response
    response = wrapped_callback(request, *callback_args, **callback_kwargs)
  File "/home/zzj/PycharmProjects/VOAM/website/views.py", line 401, in UpdateVideoDevice
    updatevideodevice = UpdateVideoDeviceForm()
NameError: global name 'UpdateVideoDeviceForm' is not defined
2016-09-10 05:29:56,191 [Thread-7:123145310715904] [django.request:170] [base:get_response] [WARNING]- Not Found: /favicon.ico
2016-09-10 05:29:56,264 [Thread-8:123145310715904] [django.request:170] [base:get_response] [WARNING]- Not Found: /favicon.ico
2016-09-10 05:30:44,737 [Thread-10:123145310715904] [django.request:170] [base:get_response] [WARNING]- Not Found: /VideoDevice/1/
2016-09-10 05:30:59,005 [Thread-11:123145310715904] [django.request:256] [base:handle_uncaught_exception] [ERROR]- Internal Server Error: /UpdateVideoDevice/1/
Traceback (most recent call last):
  File "/Library/Python/2.7/site-packages/Django-1.8.9-py2.7.egg/django/core/handlers/base.py", line 132, in get_response
    response = wrapped_callback(request, *callback_args, **callback_kwargs)
  File "/Users/ZZJMAC/PycharmProjects/VOAM/website/views.py", line 401, in UpdateVideoDevice
    updatevideodevice = UpdateVideoDeviceForm()
NameError: global name 'UpdateVideoDeviceForm' is not defined
2016-09-10 05:39:06,457 [Thread-24:123145310715904] [django.request:256] [base:handle_uncaught_exception] [ERROR]- Internal Server Error: /UpdateVideoDevice/1/
Traceback (most recent call last):
  File "/Library/Python/2.7/site-packages/Django-1.8.9-py2.7.egg/django/core/handlers/base.py", line 132, in get_response
    response = wrapped_callback(request, *callback_args, **callback_kwargs)
  File "/Users/ZZJMAC/PycharmProjects/VOAM/website/views.py", line 401, in UpdateVideoDevice
    updatevideodevice = UpdateVideoDeviceForm()
NameError: global name 'UpdateVideoDeviceForm' is not defined
2016-09-10 05:40:02,835 [Thread-28:123145310715904] [django.request:256] [base:handle_uncaught_exception] [ERROR]- Internal Server Error: /UpdateVideoDevice/1/
Traceback (most recent call last):
  File "/Library/Python/2.7/site-packages/Django-1.8.9-py2.7.egg/django/core/handlers/base.py", line 132, in get_response
    response = wrapped_callback(request, *callback_args, **callback_kwargs)
  File "/Users/ZZJMAC/PycharmProjects/VOAM/website/views.py", line 401, in UpdateVideoDevice
    updatevideodevice = UpdateVideoDeviceForm()
NameError: global name 'UpdateVideoDeviceForm' is not defined
2016-09-10 05:41:54,528 [Thread-39:123145310715904] [django.request:170] [base:get_response] [WARNING]- Not Found: /VideoDevice/1/
2016-09-10 05:42:32,018 [Thread-42:123145310715904] [django.request:256] [base:handle_uncaught_exception] [ERROR]- Internal Server Error: /UpdateVideoDevice/1/
Traceback (most recent call last):
  File "/Library/Python/2.7/site-packages/Django-1.8.9-py2.7.egg/django/core/handlers/base.py", line 132, in get_response
    response = wrapped_callback(request, *callback_args, **callback_kwargs)
  File "/Users/ZZJMAC/PycharmProjects/VOAM/website/views.py", line 401, in UpdateVideoDevice
    updatevideodevice = UpdateVideoDeviceForm()
NameError: global name 'UpdateVideoDeviceForm' is not defined
2016-09-10 05:43:22,887 [Thread-7:123145310715904] [django.request:256] [base:handle_uncaught_exception] [ERROR]- Internal Server Error: /UpdateVideoDevice/1/
Traceback (most recent call last):
  File "/Library/Python/2.7/site-packages/Django-1.8.9-py2.7.egg/django/core/handlers/base.py", line 132, in get_response
    response = wrapped_callback(request, *callback_args, **callback_kwargs)
  File "/Users/ZZJMAC/PycharmProjects/VOAM/website/views.py", line 473, in UpdateVideoDevice
    return render_to_response('AddVideoDevice.html', {'form': addvideodevice, 'grouplist': group_item,
NameError: global name 'addvideodevice' is not defined
2016-09-10 05:43:32,519 [Thread-8:123145310715904] [django.request:256] [base:handle_uncaught_exception] [ERROR]- Internal Server Error: /UpdateVideoDevice/1/
Traceback (most recent call last):
  File "/Library/Python/2.7/site-packages/Django-1.8.9-py2.7.egg/django/core/handlers/base.py", line 132, in get_response
    response = wrapped_callback(request, *callback_args, **callback_kwargs)
  File "/Users/ZZJMAC/PycharmProjects/VOAM/website/views.py", line 473, in UpdateVideoDevice
    return render_to_response('AddVideoDevice.html', {'form': addvideodevice, 'grouplist': group_item,
NameError: global name 'addvideodevice' is not defined
2016-09-10 05:45:18,340 [Thread-8:123145310715904] [django.request:170] [base:get_response] [WARNING]- Not Found: /UpdateVideoDevice/UpdateVideoDevice/1/
2016-09-11 14:05:27,575 [Thread-7:123145310715904] [django.request:170] [base:get_response] [WARNING]- Not Found: /favicon.ico
2016-09-11 14:05:27,654 [Thread-8:123145314922496] [django.request:170] [base:get_response] [WARNING]- Not Found: /favicon.ico
2016-09-11 14:40:01,979 [Thread-33:123145310715904] [django.request:170] [base:get_response] [WARNING]- Not Found: /AddVideoDevice/AddVideoDevice
2016-09-11 19:57:43,311 [Thread-7:123145310715904] [django.request:170] [base:get_response] [WARNING]- Not Found: /favicon.ico
2016-09-11 19:57:43,398 [Thread-8:123145310715904] [django.request:170] [base:get_response] [WARNING]- Not Found: /favicon.ico
2016-09-11 19:57:49,909 [Thread-9:123145310715904] [django.request:170] [base:get_response] [WARNING]- Not Found: /UpdateDevice
2016-09-11 19:57:59,633 [Thread-10:123145310715904] [django.request:170] [base:get_response] [WARNING]- Not Found: /UpdateDevice/1
2016-09-11 19:58:16,414 [Thread-11:123145310715904] [django.request:170] [base:get_response] [WARNING]- Not Found: /UpdateDevice/1/
2016-09-11 19:58:44,395 [Thread-14:123145310715904] [django.request:170] [base:get_response] [WARNING]- Not Found: /UpdateVideoDevice
2016-09-11 20:09:28,755 [Thread-2:123145310715904] [django.request:256] [base:handle_uncaught_exception] [ERROR]- Internal Server Error: /UpdateVideoDevice/1/
Traceback (most recent call last):
  File "/Library/Python/2.7/site-packages/Django-1.8.9-py2.7.egg/django/core/handlers/base.py", line 132, in get_response
    response = wrapped_callback(request, *callback_args, **callback_kwargs)
  File "/Users/ZZJMAC/PycharmProjects/VOAM/website/views.py", line 405, in UpdateVideoDevice
    videodeivce_ID = VideoDevice.objects.filter(id=videoID).id
AttributeError: 'QuerySet' object has no attribute 'id'
2016-09-11 20:12:53,952 [Thread-2:123145310715904] [django.request:256] [base:handle_uncaught_exception] [ERROR]- Internal Server Error: /UpdateVideoDevice/1/
Traceback (most recent call last):
  File "/Library/Python/2.7/site-packages/Django-1.8.9-py2.7.egg/django/core/handlers/base.py", line 132, in get_response
    response = wrapped_callback(request, *callback_args, **callback_kwargs)
  File "/Users/ZZJMAC/PycharmProjects/VOAM/website/views.py", line 406, in UpdateVideoDevice
    for item in videodevice_ID:
NameError: global name 'videodevice_ID' is not defined
2016-09-11 20:13:56,843 [Thread-2:123145310715904] [django.request:256] [base:handle_uncaught_exception] [ERROR]- Internal Server Error: /UpdateVideoDevice/1/
Traceback (most recent call last):
  File "/Library/Python/2.7/site-packages/Django-1.8.9-py2.7.egg/django/core/handlers/base.py", line 132, in get_response
    response = wrapped_callback(request, *callback_args, **callback_kwargs)
  File "/Users/ZZJMAC/PycharmProjects/VOAM/website/views.py", line 406, in UpdateVideoDevice
    for item in videodevice_ID:
NameError: global name 'videodevice_ID' is not defined
2016-09-11 20:14:15,802 [Thread-3:123145310715904] [django.request:256] [base:handle_uncaught_exception] [ERROR]- Internal Server Error: /UpdateVideoDevice/1/
Traceback (most recent call last):
  File "/Library/Python/2.7/site-packages/Django-1.8.9-py2.7.egg/django/core/handlers/base.py", line 132, in get_response
    response = wrapped_callback(request, *callback_args, **callback_kwargs)
  File "/Users/ZZJMAC/PycharmProjects/VOAM/website/views.py", line 406, in UpdateVideoDevice
    for item in videodeivce_ID:
NameError: global name 'videodevice_ID' is not defined
2016-09-11 20:15:27,447 [Thread-2:123145310715904] [django.request:256] [base:handle_uncaught_exception] [ERROR]- Internal Server Error: /UpdateVideoDevice/1/
Traceback (most recent call last):
  File "/Library/Python/2.7/site-packages/Django-1.8.9-py2.7.egg/django/core/handlers/base.py", line 132, in get_response
    response = wrapped_callback(request, *callback_args, **callback_kwargs)
  File "/Users/ZZJMAC/PycharmProjects/VOAM/website/views.py", line 405, in UpdateVideoDevice
    videodeivce_ID = VideoDevice.objects.filter(id='videoID')
  File "/Library/Python/2.7/site-packages/Django-1.8.9-py2.7.egg/django/db/models/manager.py", line 127, in manager_method
    return getattr(self.get_queryset(), name)(*args, **kwargs)
  File "/Library/Python/2.7/site-packages/Django-1.8.9-py2.7.egg/django/db/models/query.py", line 679, in filter
    return self._filter_or_exclude(False, *args, **kwargs)
  File "/Library/Python/2.7/site-packages/Django-1.8.9-py2.7.egg/django/db/models/query.py", line 697, in _filter_or_exclude
    clone.query.add_q(Q(*args, **kwargs))
  File "/Library/Python/2.7/site-packages/Django-1.8.9-py2.7.egg/django/db/models/sql/query.py", line 1310, in add_q
    clause, require_inner = self._add_q(where_part, self.used_aliases)
  File "/Library/Python/2.7/site-packages/Django-1.8.9-py2.7.egg/django/db/models/sql/query.py", line 1338, in _add_q
    allow_joins=allow_joins, split_subq=split_subq,
  File "/Library/Python/2.7/site-packages/Django-1.8.9-py2.7.egg/django/db/models/sql/query.py", line 1209, in build_filter
    condition = self.build_lookup(lookups, col, value)
  File "/Library/Python/2.7/site-packages/Django-1.8.9-py2.7.egg/django/db/models/sql/query.py", line 1102, in build_lookup
    return final_lookup(lhs, rhs)
  File "/Library/Python/2.7/site-packages/Django-1.8.9-py2.7.egg/django/db/models/lookups.py", line 105, in __init__
    self.rhs = self.get_prep_lookup()
  File "/Library/Python/2.7/site-packages/Django-1.8.9-py2.7.egg/django/db/models/lookups.py", line 143, in get_prep_lookup
    return self.lhs.output_field.get_prep_lookup(self.lookup_name, self.rhs)
  File "/Library/Python/2.7/site-packages/Django-1.8.9-py2.7.egg/django/db/models/fields/__init__.py", line 727, in get_prep_lookup
    return self.get_prep_value(value)
  File "/Library/Python/2.7/site-packages/Django-1.8.9-py2.7.egg/django/db/models/fields/__init__.py", line 985, in get_prep_value
    return int(value)
ValueError: invalid literal for int() with base 10: 'videoID'
2016-09-11 20:15:37,445 [Thread-3:123145310715904] [django.request:256] [base:handle_uncaught_exception] [ERROR]- Internal Server Error: /UpdateVideoDevice/1/
Traceback (most recent call last):
  File "/Library/Python/2.7/site-packages/Django-1.8.9-py2.7.egg/django/core/handlers/base.py", line 132, in get_response
    response = wrapped_callback(request, *callback_args, **callback_kwargs)
  File "/Users/ZZJMAC/PycharmProjects/VOAM/website/views.py", line 405, in UpdateVideoDevice
    videodeivce_ID = VideoDevice.objects.filter(id='videoID')
  File "/Library/Python/2.7/site-packages/Django-1.8.9-py2.7.egg/django/db/models/manager.py", line 127, in manager_method
    return getattr(self.get_queryset(), name)(*args, **kwargs)
  File "/Library/Python/2.7/site-packages/Django-1.8.9-py2.7.egg/django/db/models/query.py", line 679, in filter
    return self._filter_or_exclude(False, *args, **kwargs)
  File "/Library/Python/2.7/site-packages/Django-1.8.9-py2.7.egg/django/db/models/query.py", line 697, in _filter_or_exclude
    clone.query.add_q(Q(*args, **kwargs))
  File "/Library/Python/2.7/site-packages/Django-1.8.9-py2.7.egg/django/db/models/sql/query.py", line 1310, in add_q
    clause, require_inner = self._add_q(where_part, self.used_aliases)
  File "/Library/Python/2.7/site-packages/Django-1.8.9-py2.7.egg/django/db/models/sql/query.py", line 1338, in _add_q
    allow_joins=allow_joins, split_subq=split_subq,
  File "/Library/Python/2.7/site-packages/Django-1.8.9-py2.7.egg/django/db/models/sql/query.py", line 1209, in build_filter
    condition = self.build_lookup(lookups, col, value)
  File "/Library/Python/2.7/site-packages/Django-1.8.9-py2.7.egg/django/db/models/sql/query.py", line 1102, in build_lookup
    return final_lookup(lhs, rhs)
  File "/Library/Python/2.7/site-packages/Django-1.8.9-py2.7.egg/django/db/models/lookups.py", line 105, in __init__
    self.rhs = self.get_prep_lookup()
  File "/Library/Python/2.7/site-packages/Django-1.8.9-py2.7.egg/django/db/models/lookups.py", line 143, in get_prep_lookup
    return self.lhs.output_field.get_prep_lookup(self.lookup_name, self.rhs)
  File "/Library/Python/2.7/site-packages/Django-1.8.9-py2.7.egg/django/db/models/fields/__init__.py", line 727, in get_prep_lookup
    return self.get_prep_value(value)
  File "/Library/Python/2.7/site-packages/Django-1.8.9-py2.7.egg/django/db/models/fields/__init__.py", line 985, in get_prep_value
    return int(value)
ValueError: invalid literal for int() with base 10: 'videoID'
2016-09-11 20:16:10,430 [Thread-4:123145310715904] [django.request:256] [base:handle_uncaught_exception] [ERROR]- Internal Server Error: /UpdateVideoDevice/3/
Traceback (most recent call last):
  File "/Library/Python/2.7/site-packages/Django-1.8.9-py2.7.egg/django/core/handlers/base.py", line 132, in get_response
    response = wrapped_callback(request, *callback_args, **callback_kwargs)
  File "/Users/ZZJMAC/PycharmProjects/VOAM/website/views.py", line 405, in UpdateVideoDevice
    videodeivce_ID = VideoDevice.objects.filter(id='videoID')
  File "/Library/Python/2.7/site-packages/Django-1.8.9-py2.7.egg/django/db/models/manager.py", line 127, in manager_method
    return getattr(self.get_queryset(), name)(*args, **kwargs)
  File "/Library/Python/2.7/site-packages/Django-1.8.9-py2.7.egg/django/db/models/query.py", line 679, in filter
    return self._filter_or_exclude(False, *args, **kwargs)
  File "/Library/Python/2.7/site-packages/Django-1.8.9-py2.7.egg/django/db/models/query.py", line 697, in _filter_or_exclude
    clone.query.add_q(Q(*args, **kwargs))
  File "/Library/Python/2.7/site-packages/Django-1.8.9-py2.7.egg/django/db/models/sql/query.py", line 1310, in add_q
    clause, require_inner = self._add_q(where_part, self.used_aliases)
  File "/Library/Python/2.7/site-packages/Django-1.8.9-py2.7.egg/django/db/models/sql/query.py", line 1338, in _add_q
    allow_joins=allow_joins, split_subq=split_subq,
  File "/Library/Python/2.7/site-packages/Django-1.8.9-py2.7.egg/django/db/models/sql/query.py", line 1209, in build_filter
    condition = self.build_lookup(lookups, col, value)
  File "/Library/Python/2.7/site-packages/Django-1.8.9-py2.7.egg/django/db/models/sql/query.py", line 1102, in build_lookup
    return final_lookup(lhs, rhs)
  File "/Library/Python/2.7/site-packages/Django-1.8.9-py2.7.egg/django/db/models/lookups.py", line 105, in __init__
    self.rhs = self.get_prep_lookup()
  File "/Library/Python/2.7/site-packages/Django-1.8.9-py2.7.egg/django/db/models/lookups.py", line 143, in get_prep_lookup
    return self.lhs.output_field.get_prep_lookup(self.lookup_name, self.rhs)
  File "/Library/Python/2.7/site-packages/Django-1.8.9-py2.7.egg/django/db/models/fields/__init__.py", line 727, in get_prep_lookup
    return self.get_prep_value(value)
  File "/Library/Python/2.7/site-packages/Django-1.8.9-py2.7.egg/django/db/models/fields/__init__.py", line 985, in get_prep_value
    return int(value)
ValueError: invalid literal for int() with base 10: 'videoID'
2016-09-11 20:16:19,272 [Thread-5:123145310715904] [django.request:256] [base:handle_uncaught_exception] [ERROR]- Internal Server Error: /UpdateVideoDevice/3/
Traceback (most recent call last):
  File "/Library/Python/2.7/site-packages/Django-1.8.9-py2.7.egg/django/core/handlers/base.py", line 132, in get_response
    response = wrapped_callback(request, *callback_args, **callback_kwargs)
  File "/Users/ZZJMAC/PycharmProjects/VOAM/website/views.py", line 405, in UpdateVideoDevice
    videodeivce_ID = VideoDevice.objects.filter(id=videoID)
  File "/Library/Python/2.7/site-packages/Django-1.8.9-py2.7.egg/django/db/models/manager.py", line 127, in manager_method
    return getattr(self.get_queryset(), name)(*args, **kwargs)
  File "/Library/Python/2.7/site-packages/Django-1.8.9-py2.7.egg/django/db/models/query.py", line 679, in filter
    return self._filter_or_exclude(False, *args, **kwargs)
  File "/Library/Python/2.7/site-packages/Django-1.8.9-py2.7.egg/django/db/models/query.py", line 697, in _filter_or_exclude
    clone.query.add_q(Q(*args, **kwargs))
  File "/Library/Python/2.7/site-packages/Django-1.8.9-py2.7.egg/django/db/models/sql/query.py", line 1310, in add_q
    clause, require_inner = self._add_q(where_part, self.used_aliases)
  File "/Library/Python/2.7/site-packages/Django-1.8.9-py2.7.egg/django/db/models/sql/query.py", line 1338, in _add_q
    allow_joins=allow_joins, split_subq=split_subq,
  File "/Library/Python/2.7/site-packages/Django-1.8.9-py2.7.egg/django/db/models/sql/query.py", line 1209, in build_filter
    condition = self.build_lookup(lookups, col, value)
  File "/Library/Python/2.7/site-packages/Django-1.8.9-py2.7.egg/django/db/models/sql/query.py", line 1102, in build_lookup
    return final_lookup(lhs, rhs)
  File "/Library/Python/2.7/site-packages/Django-1.8.9-py2.7.egg/django/db/models/lookups.py", line 105, in __init__
    self.rhs = self.get_prep_lookup()
  File "/Library/Python/2.7/site-packages/Django-1.8.9-py2.7.egg/django/db/models/lookups.py", line 143, in get_prep_lookup
    return self.lhs.output_field.get_prep_lookup(self.lookup_name, self.rhs)
  File "/Library/Python/2.7/site-packages/Django-1.8.9-py2.7.egg/django/db/models/fields/__init__.py", line 727, in get_prep_lookup
    return self.get_prep_value(value)
  File "/Library/Python/2.7/site-packages/Django-1.8.9-py2.7.egg/django/db/models/fields/__init__.py", line 985, in get_prep_value
    return int(value)
ValueError: invalid literal for int() with base 10: 'videoID'
2016-09-12 01:08:23,709 [Thread-7:123145310715904] [django.request:170] [base:get_response] [WARNING]- Not Found: /UpdateVideoDevice/
2016-09-12 01:09:21,447 [Thread-13:123145310715904] [django.request:256] [base:handle_uncaught_exception] [ERROR]- Internal Server Error: /UpdateVideoDevice/1
Traceback (most recent call last):
  File "/Library/Python/2.7/site-packages/Django-1.8.9-py2.7.egg/django/core/handlers/base.py", line 108, in get_response
    response = middleware_method(request)
  File "/Library/Python/2.7/site-packages/Django-1.8.9-py2.7.egg/django/middleware/common.py", line 84, in process_request
    "settings.") % (new_url[0], new_url[1]))
RuntimeError: You called this URL via POST, but the URL doesn't end in a slash and you have APPEND_SLASH set. Django can't redirect to the slash URL while maintaining POST data. Change your form to point to 127.0.0.1:8000/UpdateVideoDevice/1/ (note the trailing slash), or set APPEND_SLASH=False in your Django settings.
2016-09-12 01:09:49,945 [Thread-17:123145310715904] [django.request:256] [base:handle_uncaught_exception] [ERROR]- Internal Server Error: /UpdateVideoDevice/1
Traceback (most recent call last):
  File "/Library/Python/2.7/site-packages/Django-1.8.9-py2.7.egg/django/core/handlers/base.py", line 108, in get_response
    response = middleware_method(request)
  File "/Library/Python/2.7/site-packages/Django-1.8.9-py2.7.egg/django/middleware/common.py", line 84, in process_request
    "settings.") % (new_url[0], new_url[1]))
RuntimeError: You called this URL via POST, but the URL doesn't end in a slash and you have APPEND_SLASH set. Django can't redirect to the slash URL while maintaining POST data. Change your form to point to 127.0.0.1:8000/UpdateVideoDevice/1/ (note the trailing slash), or set APPEND_SLASH=False in your Django settings.
2016-09-12 01:44:35,753 [Thread-10:123145323335680] [django.request:256] [base:handle_uncaught_exception] [ERROR]- Internal Server Error: /UpdateVideoDevice/1/
Traceback (most recent call last):
  File "/Library/Python/2.7/site-packages/Django-1.8.9-py2.7.egg/django/core/handlers/base.py", line 132, in get_response
    response = wrapped_callback(request, *callback_args, **callback_kwargs)
  File "/Users/ZZJMAC/PycharmProjects/VOAM/website/views.py", line 427, in UpdateVideoDevice
    print 'ID:' + id + 'pid:' + pid + 'name:' + name + 'group:' + group + 'region:' + region + 'direction:' + direction + 'vtype:' + vtype + 'brand:' + brand + 'dtype:' + dtype + 'username' + username + 'password:' + password + 'gpslon:' + gpslon + 'gpswei' + gpswei
TypeError: cannot concatenate 'str' and 'builtin_function_or_method' objects
2016-09-12 15:19:10,507 [Thread-7:140279154243328] [django.request:170] [base:get_response] [WARNING]- Not Found: /favicon.ico
