2016-09-05 09:08:44,992 [Thread-3:140016482998016] [django.request:256] [base:handle_uncaught_exception] [ERROR]- Internal Server Error: /AddBasicInfo/
Traceback (most recent call last):
  File "/usr/local/lib/python2.7/dist-packages/django/core/handlers/base.py", line 132, in get_response
    response = wrapped_callback(request, *callback_args, **callback_kwargs)
  File "/home/zzj/PycharmProjects/VOAM/website/views.py", line 37, in AddBasicInfo
    return render_to_response('AddBasicInfo.html', {'devicestatusform': devicestatusform,'devicegroupform':devicegroupform,'deviceregionform':deviceregionform,'videodirectionform':videodirectionform,'videotypeform':videotypeform,'devicebrandform':devicebrandform,'devicetypeform':devicetypeform,'devicebrandid':devicebrandid})
  File "/usr/local/lib/python2.7/dist-packages/django/shortcuts.py", line 39, in render_to_response
    content = loader.render_to_string(template_name, context, using=using)
  File "/usr/local/lib/python2.7/dist-packages/django/template/loader.py", line 99, in render_to_string
    return template.render(context, request)
  File "/usr/local/lib/python2.7/dist-packages/django/template/backends/django.py", line 74, in render
    return self.template.render(context)
  File "/usr/local/lib/python2.7/dist-packages/django/template/base.py", line 210, in render
    return self._render(context)
  File "/usr/local/lib/python2.7/dist-packages/django/template/base.py", line 202, in _render
    return self.nodelist.render(context)
  File "/usr/local/lib/python2.7/dist-packages/django/template/base.py", line 905, in render
    bit = self.render_node(node, context)
  File "/usr/local/lib/python2.7/dist-packages/django/template/debug.py", line 79, in render_node
    return node.render(context)
  File "/usr/local/lib/python2.7/dist-packages/django/template/defaulttags.py", line 162, in render
    len_values = len(values)
  File "/usr/local/lib/python2.7/dist-packages/django/db/models/query.py", line 144, in __len__
    self._fetch_all()
  File "/usr/local/lib/python2.7/dist-packages/django/db/models/query.py", line 965, in _fetch_all
    self._result_cache = list(self.iterator())
  File "/usr/local/lib/python2.7/dist-packages/django/db/models/query.py", line 238, in iterator
    results = compiler.execute_sql()
  File "/usr/local/lib/python2.7/dist-packages/django/db/models/sql/compiler.py", line 840, in execute_sql
    cursor.execute(sql, params)
  File "/usr/local/lib/python2.7/dist-packages/django/db/backends/utils.py", line 79, in execute
    return super(CursorDebugWrapper, self).execute(sql, params)
  File "/usr/local/lib/python2.7/dist-packages/django/db/backends/utils.py", line 64, in execute
    return self.cursor.execute(sql, params)
  File "/usr/local/lib/python2.7/dist-packages/django/db/utils.py", line 98, in __exit__
    six.reraise(dj_exc_type, dj_exc_value, traceback)
  File "/usr/local/lib/python2.7/dist-packages/django/db/backends/utils.py", line 64, in execute
    return self.cursor.execute(sql, params)
  File "/usr/local/lib/python2.7/dist-packages/django/db/backends/mysql/base.py", line 124, in execute
    return self.cursor.execute(query, args)
  File "/usr/lib/python2.7/dist-packages/MySQLdb/cursors.py", line 226, in execute
    self.errorhandler(self, exc, value)
  File "/usr/lib/python2.7/dist-packages/MySQLdb/connections.py", line 36, in defaulterrorhandler
    raise errorvalue
ProgrammingError: (1146, "Table 'voam.website_devicebrand' doesn't exist")
2016-09-05 09:08:46,065 [Thread-4:140016482998016] [django.request:170] [base:get_response] [WARNING]- Not Found: /favicon.ico
2016-09-05 09:24:35,314 [Thread-7:140334258775808] [django.request:256] [base:handle_uncaught_exception] [ERROR]- Internal Server Error: /AddBasicInfo/
Traceback (most recent call last):
  File "/usr/local/lib/python2.7/dist-packages/django/core/handlers/base.py", line 132, in get_response
    response = wrapped_callback(request, *callback_args, **callback_kwargs)
  File "/home/zzj/PycharmProjects/VOAM/website/views.py", line 26, in AddBasicInfo
    result = DeviceStatus.objects.filter(devicestatus=devicestatus).count()
  File "/usr/local/lib/python2.7/dist-packages/django/db/models/manager.py", line 127, in manager_method
    return getattr(self.get_queryset(), name)(*args, **kwargs)
  File "/usr/local/lib/python2.7/dist-packages/django/db/models/query.py", line 679, in filter
    return self._filter_or_exclude(False, *args, **kwargs)
  File "/usr/local/lib/python2.7/dist-packages/django/db/models/query.py", line 697, in _filter_or_exclude
    clone.query.add_q(Q(*args, **kwargs))
  File "/usr/local/lib/python2.7/dist-packages/django/db/models/sql/query.py", line 1310, in add_q
    clause, require_inner = self._add_q(where_part, self.used_aliases)
  File "/usr/local/lib/python2.7/dist-packages/django/db/models/sql/query.py", line 1338, in _add_q
    allow_joins=allow_joins, split_subq=split_subq,
  File "/usr/local/lib/python2.7/dist-packages/django/db/models/sql/query.py", line 1150, in build_filter
    lookups, parts, reffed_expression = self.solve_lookup_type(arg)
  File "/usr/local/lib/python2.7/dist-packages/django/db/models/sql/query.py", line 1036, in solve_lookup_type
    _, field, _, lookup_parts = self.names_to_path(lookup_splitted, self.get_meta())
  File "/usr/local/lib/python2.7/dist-packages/django/db/models/sql/query.py", line 1397, in names_to_path
    "Choices are: %s" % (name, ", ".join(available)))
FieldError: Cannot resolve keyword 'devicestatus' into field. Choices are: id, name
2016-09-05 09:29:33,019 [Thread-3:140575047071488] [django.request:256] [base:handle_uncaught_exception] [ERROR]- Internal Server Error: /AddBasicInfo/
Traceback (most recent call last):
  File "/usr/local/lib/python2.7/dist-packages/django/core/handlers/base.py", line 132, in get_response
    response = wrapped_callback(request, *callback_args, **callback_kwargs)
  File "/home/zzj/PycharmProjects/VOAM/website/views.py", line 27, in AddBasicInfo
    result = DeviceStatus.objects.filter(devicestatus=devicestatus).count()
  File "/usr/local/lib/python2.7/dist-packages/django/db/models/manager.py", line 127, in manager_method
    return getattr(self.get_queryset(), name)(*args, **kwargs)
  File "/usr/local/lib/python2.7/dist-packages/django/db/models/query.py", line 679, in filter
    return self._filter_or_exclude(False, *args, **kwargs)
  File "/usr/local/lib/python2.7/dist-packages/django/db/models/query.py", line 697, in _filter_or_exclude
    clone.query.add_q(Q(*args, **kwargs))
  File "/usr/local/lib/python2.7/dist-packages/django/db/models/sql/query.py", line 1310, in add_q
    clause, require_inner = self._add_q(where_part, self.used_aliases)
  File "/usr/local/lib/python2.7/dist-packages/django/db/models/sql/query.py", line 1338, in _add_q
    allow_joins=allow_joins, split_subq=split_subq,
  File "/usr/local/lib/python2.7/dist-packages/django/db/models/sql/query.py", line 1150, in build_filter
    lookups, parts, reffed_expression = self.solve_lookup_type(arg)
  File "/usr/local/lib/python2.7/dist-packages/django/db/models/sql/query.py", line 1036, in solve_lookup_type
    _, field, _, lookup_parts = self.names_to_path(lookup_splitted, self.get_meta())
  File "/usr/local/lib/python2.7/dist-packages/django/db/models/sql/query.py", line 1397, in names_to_path
    "Choices are: %s" % (name, ", ".join(available)))
FieldError: Cannot resolve keyword 'devicestatus' into field. Choices are: id, name
2016-09-05 09:35:02,816 [Thread-3:140154758657792] [django.request:256] [base:handle_uncaught_exception] [ERROR]- Internal Server Error: /AddBasicInfo/
Traceback (most recent call last):
  File "/usr/local/lib/python2.7/dist-packages/django/core/handlers/base.py", line 132, in get_response
    response = wrapped_callback(request, *callback_args, **callback_kwargs)
  File "/home/zzj/PycharmProjects/VOAM/website/views.py", line 28, in AddBasicInfo
    result = DeviceStatus.objects.filter(devicestatus=devicestatus).count()
  File "/usr/local/lib/python2.7/dist-packages/django/db/models/manager.py", line 127, in manager_method
    return getattr(self.get_queryset(), name)(*args, **kwargs)
  File "/usr/local/lib/python2.7/dist-packages/django/db/models/query.py", line 679, in filter
    return self._filter_or_exclude(False, *args, **kwargs)
  File "/usr/local/lib/python2.7/dist-packages/django/db/models/query.py", line 697, in _filter_or_exclude
    clone.query.add_q(Q(*args, **kwargs))
  File "/usr/local/lib/python2.7/dist-packages/django/db/models/sql/query.py", line 1310, in add_q
    clause, require_inner = self._add_q(where_part, self.used_aliases)
  File "/usr/local/lib/python2.7/dist-packages/django/db/models/sql/query.py", line 1338, in _add_q
    allow_joins=allow_joins, split_subq=split_subq,
  File "/usr/local/lib/python2.7/dist-packages/django/db/models/sql/query.py", line 1150, in build_filter
    lookups, parts, reffed_expression = self.solve_lookup_type(arg)
  File "/usr/local/lib/python2.7/dist-packages/django/db/models/sql/query.py", line 1036, in solve_lookup_type
    _, field, _, lookup_parts = self.names_to_path(lookup_splitted, self.get_meta())
  File "/usr/local/lib/python2.7/dist-packages/django/db/models/sql/query.py", line 1397, in names_to_path
    "Choices are: %s" % (name, ", ".join(available)))
FieldError: Cannot resolve keyword 'devicestatus' into field. Choices are: id, name
2016-09-05 09:36:41,076 [Thread-5:140154758657792] [django.request:256] [base:handle_uncaught_exception] [ERROR]- Internal Server Error: /AddBasicInfo/
Traceback (most recent call last):
  File "/usr/local/lib/python2.7/dist-packages/django/core/handlers/base.py", line 132, in get_response
    response = wrapped_callback(request, *callback_args, **callback_kwargs)
  File "/home/zzj/PycharmProjects/VOAM/website/views.py", line 28, in AddBasicInfo
    result = DeviceStatus.objects.filter(devicestatus=devicestatus).count()
  File "/usr/local/lib/python2.7/dist-packages/django/db/models/manager.py", line 127, in manager_method
    return getattr(self.get_queryset(), name)(*args, **kwargs)
  File "/usr/local/lib/python2.7/dist-packages/django/db/models/query.py", line 679, in filter
    return self._filter_or_exclude(False, *args, **kwargs)
  File "/usr/local/lib/python2.7/dist-packages/django/db/models/query.py", line 697, in _filter_or_exclude
    clone.query.add_q(Q(*args, **kwargs))
  File "/usr/local/lib/python2.7/dist-packages/django/db/models/sql/query.py", line 1310, in add_q
    clause, require_inner = self._add_q(where_part, self.used_aliases)
  File "/usr/local/lib/python2.7/dist-packages/django/db/models/sql/query.py", line 1338, in _add_q
    allow_joins=allow_joins, split_subq=split_subq,
  File "/usr/local/lib/python2.7/dist-packages/django/db/models/sql/query.py", line 1150, in build_filter
    lookups, parts, reffed_expression = self.solve_lookup_type(arg)
  File "/usr/local/lib/python2.7/dist-packages/django/db/models/sql/query.py", line 1036, in solve_lookup_type
    _, field, _, lookup_parts = self.names_to_path(lookup_splitted, self.get_meta())
  File "/usr/local/lib/python2.7/dist-packages/django/db/models/sql/query.py", line 1397, in names_to_path
    "Choices are: %s" % (name, ", ".join(available)))
FieldError: Cannot resolve keyword 'devicestatus' into field. Choices are: id, name
2016-09-05 09:45:04,512 [Thread-3:139905444968192] [django.request:256] [base:handle_uncaught_exception] [ERROR]- Internal Server Error: /AddBasicInfo/
Traceback (most recent call last):
  File "/usr/local/lib/python2.7/dist-packages/django/core/handlers/base.py", line 132, in get_response
    response = wrapped_callback(request, *callback_args, **callback_kwargs)
  File "/home/zzj/PycharmProjects/VOAM/website/views.py", line 28, in AddBasicInfo
    result = DeviceStatus.objects.filter(devicestatus=devicestatus).count()
  File "/usr/local/lib/python2.7/dist-packages/django/db/models/manager.py", line 127, in manager_method
    return getattr(self.get_queryset(), name)(*args, **kwargs)
  File "/usr/local/lib/python2.7/dist-packages/django/db/models/query.py", line 679, in filter
    return self._filter_or_exclude(False, *args, **kwargs)
  File "/usr/local/lib/python2.7/dist-packages/django/db/models/query.py", line 697, in _filter_or_exclude
    clone.query.add_q(Q(*args, **kwargs))
  File "/usr/local/lib/python2.7/dist-packages/django/db/models/sql/query.py", line 1310, in add_q
    clause, require_inner = self._add_q(where_part, self.used_aliases)
  File "/usr/local/lib/python2.7/dist-packages/django/db/models/sql/query.py", line 1338, in _add_q
    allow_joins=allow_joins, split_subq=split_subq,
  File "/usr/local/lib/python2.7/dist-packages/django/db/models/sql/query.py", line 1150, in build_filter
    lookups, parts, reffed_expression = self.solve_lookup_type(arg)
  File "/usr/local/lib/python2.7/dist-packages/django/db/models/sql/query.py", line 1036, in solve_lookup_type
    _, field, _, lookup_parts = self.names_to_path(lookup_splitted, self.get_meta())
  File "/usr/local/lib/python2.7/dist-packages/django/db/models/sql/query.py", line 1397, in names_to_path
    "Choices are: %s" % (name, ", ".join(available)))
FieldError: Cannot resolve keyword 'devicestatus' into field. Choices are: id, name
2016-09-05 09:45:32,672 [Thread-3:139764313126656] [django.request:256] [base:handle_uncaught_exception] [ERROR]- Internal Server Error: /AddBasicInfo/
Traceback (most recent call last):
  File "/usr/local/lib/python2.7/dist-packages/django/core/handlers/base.py", line 132, in get_response
    response = wrapped_callback(request, *callback_args, **callback_kwargs)
  File "/home/zzj/PycharmProjects/VOAM/website/views.py", line 31, in AddBasicInfo
    DeviceStatus.objects.create(devicestatus=devicestatus)
  File "/usr/local/lib/python2.7/dist-packages/django/db/models/manager.py", line 127, in manager_method
    return getattr(self.get_queryset(), name)(*args, **kwargs)
  File "/usr/local/lib/python2.7/dist-packages/django/db/models/query.py", line 346, in create
    obj = self.model(**kwargs)
  File "/usr/local/lib/python2.7/dist-packages/django/db/models/base.py", line 480, in __init__
    raise TypeError("'%s' is an invalid keyword argument for this function" % list(kwargs)[0])
TypeError: 'devicestatus' is an invalid keyword argument for this function
2016-09-05 11:45:08,497 [Thread-2:140169989203712] [django.request:256] [base:handle_uncaught_exception] [ERROR]- Internal Server Error: /AddBasicInfo/
Traceback (most recent call last):
  File "/usr/local/lib/python2.7/dist-packages/django/core/handlers/base.py", line 132, in get_response
    response = wrapped_callback(request, *callback_args, **callback_kwargs)
  File "/home/zzj/PycharmProjects/VOAM/website/views.py", line 29, in AddBasicInfo
    print '收到的消息：%s %s %s %s %s %s %s '%(devicestatus,devicegroup,deviceregion,videodirection,videotype,devicebrand,devicetype)
UnicodeDecodeError: 'ascii' codec can't decode byte 0xe6 in position 0: ordinal not in range(128)
2016-09-05 11:49:24,282 [Thread-3:139811529537280] [django.request:256] [base:handle_uncaught_exception] [ERROR]- Internal Server Error: /AddBasicInfo/
Traceback (most recent call last):
  File "/usr/local/lib/python2.7/dist-packages/django/core/handlers/base.py", line 151, in get_response
    % (callback.__module__, view_name))
ValueError: The view website.views.AddBasicInfo didn't return an HttpResponse object. It returned None instead.
2016-09-05 11:50:03,394 [Thread-3:140191759070976] [django.request:256] [base:handle_uncaught_exception] [ERROR]- Internal Server Error: /AddBasicInfo/
Traceback (most recent call last):
  File "/usr/local/lib/python2.7/dist-packages/django/core/handlers/base.py", line 151, in get_response
    % (callback.__module__, view_name))
ValueError: The view website.views.AddBasicInfo didn't return an HttpResponse object. It returned None instead.
2016-09-05 11:50:49,025 [Thread-3:140301184968448] [django.request:256] [base:handle_uncaught_exception] [ERROR]- Internal Server Error: /AddBasicInfo/
Traceback (most recent call last):
  File "/usr/local/lib/python2.7/dist-packages/django/core/handlers/base.py", line 151, in get_response
    % (callback.__module__, view_name))
ValueError: The view website.views.AddBasicInfo didn't return an HttpResponse object. It returned None instead.
2016-09-05 11:51:28,816 [Thread-3:139757289719552] [django.request:256] [base:handle_uncaught_exception] [ERROR]- Internal Server Error: /AddBasicInfo/
Traceback (most recent call last):
  File "/usr/local/lib/python2.7/dist-packages/django/core/handlers/base.py", line 151, in get_response
    % (callback.__module__, view_name))
ValueError: The view website.views.AddBasicInfo didn't return an HttpResponse object. It returned None instead.
2016-09-05 12:13:50,197 [Thread-3:140689405601536] [django.request:256] [base:handle_uncaught_exception] [ERROR]- Internal Server Error: /AddBasicInfo/
Traceback (most recent call last):
  File "/usr/local/lib/python2.7/dist-packages/django/core/handlers/base.py", line 151, in get_response
    % (callback.__module__, view_name))
ValueError: The view website.views.AddBasicInfo didn't return an HttpResponse object. It returned None instead.
2016-09-05 12:14:48,700 [Thread-3:140421487191808] [django.request:256] [base:handle_uncaught_exception] [ERROR]- Internal Server Error: /AddBasicInfo/
Traceback (most recent call last):
  File "/usr/local/lib/python2.7/dist-packages/django/core/handlers/base.py", line 151, in get_response
    % (callback.__module__, view_name))
ValueError: The view website.views.AddBasicInfo didn't return an HttpResponse object. It returned None instead.
2016-09-05 12:16:30,952 [Thread-3:140347717375744] [django.request:256] [base:handle_uncaught_exception] [ERROR]- Internal Server Error: /AddBasicInfo/
Traceback (most recent call last):
  File "/usr/local/lib/python2.7/dist-packages/django/core/handlers/base.py", line 151, in get_response
    % (callback.__module__, view_name))
ValueError: The view website.views.AddBasicInfo didn't return an HttpResponse object. It returned None instead.
2016-09-05 17:24:33,217 [Thread-3:139668740937472] [django.request:256] [base:handle_uncaught_exception] [ERROR]- Internal Server Error: /AddBasicInfo/
Traceback (most recent call last):
  File "/usr/local/lib/python2.7/dist-packages/django/core/handlers/base.py", line 151, in get_response
    % (callback.__module__, view_name))
ValueError: The view website.views.AddBasicInfo didn't return an HttpResponse object. It returned None instead.
2016-09-05 17:25:07,848 [Thread-3:140264798586624] [django.request:256] [base:handle_uncaught_exception] [ERROR]- Internal Server Error: /AddBasicInfo/
Traceback (most recent call last):
  File "/usr/local/lib/python2.7/dist-packages/django/core/handlers/base.py", line 151, in get_response
    % (callback.__module__, view_name))
ValueError: The view website.views.AddBasicInfo didn't return an HttpResponse object. It returned None instead.
2016-09-05 17:26:17,118 [Thread-2:139968018118400] [django.request:256] [base:handle_uncaught_exception] [ERROR]- Internal Server Error: /AddBasicInfo/
Traceback (most recent call last):
  File "/usr/local/lib/python2.7/dist-packages/django/core/handlers/base.py", line 119, in get_response
    resolver_match = resolver.resolve(request.path_info)
  File "/usr/local/lib/python2.7/dist-packages/django/core/urlresolvers.py", line 365, in resolve
    for pattern in self.url_patterns:
  File "/usr/local/lib/python2.7/dist-packages/django/core/urlresolvers.py", line 401, in url_patterns
    patterns = getattr(self.urlconf_module, "urlpatterns", self.urlconf_module)
  File "/usr/local/lib/python2.7/dist-packages/django/core/urlresolvers.py", line 395, in urlconf_module
    self._urlconf_module = import_module(self.urlconf_name)
  File "/usr/lib/python2.7/importlib/__init__.py", line 37, in import_module
    __import__(name)
  File "/home/zzj/PycharmProjects/VOAM/VOAM/urls.py", line 17, in <module>
    from website.views import Index,AddVideoDevice,AddBasicInfo
  File "/home/zzj/PycharmProjects/VOAM/website/views.py", line 54
    elif devicegroup != 0:
       ^
SyntaxError: invalid syntax
2016-09-05 17:30:46,603 [Thread-5:139968018118400] [django.request:256] [base:handle_uncaught_exception] [ERROR]- Internal Server Error: /AddBasicInfo/
Traceback (most recent call last):
  File "/usr/local/lib/python2.7/dist-packages/django/core/handlers/base.py", line 151, in get_response
    % (callback.__module__, view_name))
ValueError: The view website.views.AddBasicInfo didn't return an HttpResponse object. It returned None instead.
2016-09-05 17:33:26,174 [Thread-3:139731123828480] [django.request:256] [base:handle_uncaught_exception] [ERROR]- Internal Server Error: /AddBasicInfo/
Traceback (most recent call last):
  File "/usr/local/lib/python2.7/dist-packages/django/core/handlers/base.py", line 151, in get_response
    % (callback.__module__, view_name))
ValueError: The view website.views.AddBasicInfo didn't return an HttpResponse object. It returned None instead.
2016-09-05 17:35:33,892 [Thread-3:139812047648512] [django.request:256] [base:handle_uncaught_exception] [ERROR]- Internal Server Error: /AddBasicInfo/
Traceback (most recent call last):
  File "/usr/local/lib/python2.7/dist-packages/django/core/handlers/base.py", line 151, in get_response
    % (callback.__module__, view_name))
ValueError: The view website.views.AddBasicInfo didn't return an HttpResponse object. It returned None instead.
2016-09-05 19:14:46,507 [Thread-3:123145310715904] [django.request:170] [base:get_response] [WARNING]- Not Found: /favicon.ico
2016-09-05 19:14:46,540 [Thread-4:123145310715904] [django.request:170] [base:get_response] [WARNING]- Not Found: /favicon.ico
2016-09-05 19:14:52,308 [Thread-5:123145310715904] [django.request:256] [base:handle_uncaught_exception] [ERROR]- Internal Server Error: /AddBasicInfo/
Traceback (most recent call last):
  File "/Library/Python/2.7/site-packages/Django-1.8.9-py2.7.egg/django/core/handlers/base.py", line 151, in get_response
    % (callback.__module__, view_name))
ValueError: The view website.views.AddBasicInfo didn't return an HttpResponse object. It returned None instead.
2016-09-05 19:19:43,559 [Thread-3:123145310715904] [django.request:256] [base:handle_uncaught_exception] [ERROR]- Internal Server Error: /AddBasicInfo/
Traceback (most recent call last):
  File "/Library/Python/2.7/site-packages/Django-1.8.9-py2.7.egg/django/core/handlers/base.py", line 151, in get_response
    % (callback.__module__, view_name))
ValueError: The view website.views.AddBasicInfo didn't return an HttpResponse object. It returned None instead.
2016-09-05 21:07:23,012 [Thread-2:123145310715904] [django.request:256] [base:handle_uncaught_exception] [ERROR]- Internal Server Error: /AddBasicInfo/
Traceback (most recent call last):
  File "/Library/Python/2.7/site-packages/Django-1.8.9-py2.7.egg/django/core/handlers/base.py", line 132, in get_response
    response = wrapped_callback(request, *callback_args, **callback_kwargs)
  File "/Users/ZZJMAC/PycharmProjects/VOAM/website/views.py", line 191, in AddBasicInfo
    DeviceType.objects.create(brandid=devicebrandid,name=devicetype)
  File "/Library/Python/2.7/site-packages/Django-1.8.9-py2.7.egg/django/db/models/manager.py", line 127, in manager_method
    return getattr(self.get_queryset(), name)(*args, **kwargs)
  File "/Library/Python/2.7/site-packages/Django-1.8.9-py2.7.egg/django/db/models/query.py", line 346, in create
    obj = self.model(**kwargs)
  File "/Library/Python/2.7/site-packages/Django-1.8.9-py2.7.egg/django/db/models/base.py", line 468, in __init__
    setattr(self, field.name, rel_obj)
  File "/Library/Python/2.7/site-packages/Django-1.8.9-py2.7.egg/django/db/models/fields/related.py", line 642, in __set__
    self.field.rel.to._meta.object_name,
ValueError: Cannot assign "u'1'": "DeviceType.brandid" must be a "DeviceBrand" instance.
2016-09-05 21:09:17,778 [Thread-3:123145310715904] [django.request:256] [base:handle_uncaught_exception] [ERROR]- Internal Server Error: /AddBasicInfo/
Traceback (most recent call last):
  File "/Library/Python/2.7/site-packages/Django-1.8.9-py2.7.egg/django/core/handlers/base.py", line 132, in get_response
    response = wrapped_callback(request, *callback_args, **callback_kwargs)
  File "/Users/ZZJMAC/PycharmProjects/VOAM/website/views.py", line 192, in AddBasicInfo
    DeviceType.objects.create(brandid=devicebrandid,name=devicetype)
  File "/Library/Python/2.7/site-packages/Django-1.8.9-py2.7.egg/django/db/models/manager.py", line 127, in manager_method
    return getattr(self.get_queryset(), name)(*args, **kwargs)
  File "/Library/Python/2.7/site-packages/Django-1.8.9-py2.7.egg/django/db/models/query.py", line 346, in create
    obj = self.model(**kwargs)
  File "/Library/Python/2.7/site-packages/Django-1.8.9-py2.7.egg/django/db/models/base.py", line 468, in __init__
    setattr(self, field.name, rel_obj)
  File "/Library/Python/2.7/site-packages/Django-1.8.9-py2.7.egg/django/db/models/fields/related.py", line 642, in __set__
    self.field.rel.to._meta.object_name,
ValueError: Cannot assign "u'1'": "DeviceType.brandid" must be a "DeviceBrand" instance.
2016-09-05 21:12:08,973 [Thread-2:123145310715904] [django.request:256] [base:handle_uncaught_exception] [ERROR]- Internal Server Error: /AddBasicInfo/
Traceback (most recent call last):
  File "/Library/Python/2.7/site-packages/Django-1.8.9-py2.7.egg/django/core/handlers/base.py", line 132, in get_response
    response = wrapped_callback(request, *callback_args, **callback_kwargs)
  File "/Users/ZZJMAC/PycharmProjects/VOAM/website/views.py", line 190, in AddBasicInfo
    result = DeviceType.objects.filter(name=devicetype,brandid_id=devicebrandid).count()
  File "/Library/Python/2.7/site-packages/Django-1.8.9-py2.7.egg/django/db/models/manager.py", line 127, in manager_method
    return getattr(self.get_queryset(), name)(*args, **kwargs)
  File "/Library/Python/2.7/site-packages/Django-1.8.9-py2.7.egg/django/db/models/query.py", line 679, in filter
    return self._filter_or_exclude(False, *args, **kwargs)
  File "/Library/Python/2.7/site-packages/Django-1.8.9-py2.7.egg/django/db/models/query.py", line 697, in _filter_or_exclude
    clone.query.add_q(Q(*args, **kwargs))
  File "/Library/Python/2.7/site-packages/Django-1.8.9-py2.7.egg/django/db/models/sql/query.py", line 1310, in add_q
    clause, require_inner = self._add_q(where_part, self.used_aliases)
  File "/Library/Python/2.7/site-packages/Django-1.8.9-py2.7.egg/django/db/models/sql/query.py", line 1338, in _add_q
    allow_joins=allow_joins, split_subq=split_subq,
  File "/Library/Python/2.7/site-packages/Django-1.8.9-py2.7.egg/django/db/models/sql/query.py", line 1200, in build_filter
    lookups, value)
  File "/Library/Python/2.7/site-packages/Django-1.8.9-py2.7.egg/django/db/models/fields/related.py", line 1761, in get_lookup_constraint
    lookup_class(target.get_col(alias, source), val), AND)
  File "/Library/Python/2.7/site-packages/Django-1.8.9-py2.7.egg/django/db/models/lookups.py", line 105, in __init__
    self.rhs = self.get_prep_lookup()
  File "/Library/Python/2.7/site-packages/Django-1.8.9-py2.7.egg/django/db/models/lookups.py", line 143, in get_prep_lookup
    return self.lhs.output_field.get_prep_lookup(self.lookup_name, self.rhs)
  File "/Library/Python/2.7/site-packages/Django-1.8.9-py2.7.egg/django/db/models/fields/__init__.py", line 727, in get_prep_lookup
    return self.get_prep_value(value)
  File "/Library/Python/2.7/site-packages/Django-1.8.9-py2.7.egg/django/db/models/fields/__init__.py", line 985, in get_prep_value
    return int(value)
ValueError: invalid literal for int() with base 10: ''
2016-09-05 23:56:29,866 [Thread-6:123145310715904] [django.request:256] [base:handle_uncaught_exception] [ERROR]- Internal Server Error: /
Traceback (most recent call last):
  File "/Library/Python/2.7/site-packages/Django-1.8.9-py2.7.egg/django/core/handlers/base.py", line 132, in get_response
    response = wrapped_callback(request, *callback_args, **callback_kwargs)
  File "/Users/ZZJMAC/PycharmProjects/VOAM/website/views.py", line 10, in Index
    good_serverlist = ServerHostDevice.objects.filter()
AttributeError: type object 'ServerHostDevice' has no attribute 'objects'
2016-09-05 23:57:35,046 [Thread-7:123145310715904] [django.request:256] [base:handle_uncaught_exception] [ERROR]- Internal Server Error: /
Traceback (most recent call last):
  File "/Library/Python/2.7/site-packages/Django-1.8.9-py2.7.egg/django/core/handlers/base.py", line 132, in get_response
    response = wrapped_callback(request, *callback_args, **callback_kwargs)
  File "/Users/ZZJMAC/PycharmProjects/VOAM/website/views.py", line 10, in Index
    good_serverlist = DeviceGroup.objects.all()
AttributeError: type object 'ServerHostDevice' has no attribute 'objects'
2016-09-05 23:57:44,204 [Thread-2:123145310715904] [django.request:256] [base:handle_uncaught_exception] [ERROR]- Internal Server Error: /
Traceback (most recent call last):
  File "/Library/Python/2.7/site-packages/Django-1.8.9-py2.7.egg/django/core/handlers/base.py", line 151, in get_response
    % (callback.__module__, view_name))
ValueError: The view website.views.Index didn't return an HttpResponse object. It returned None instead.
